Workbook

Sheet Master
A1: Denmark
A2: 1993-Q1 | B2: 1993-Q2 | C2: 1993-Q3 | D2: 1993-Q4 | E2: 1994-Q1 | F2: 1994-Q2 | G2: 1994-Q3 | H2: 1994-Q4 | I2: 1995-Q1 | J2: 1995-Q2 | K2: 1995-Q3 | L2: 1995-Q4 | M2: 1996-Q1 | N2: 1996-Q2 | O2: 1996-Q3 | P2: 1996-Q4 | Q2: 1997-Q1 | R2: 1997-Q2 | S2: 1997-Q3 | T2: 1997-Q4 | U2: 1998-Q1 | V2: 1998-Q2 | W2: 1998-Q3 | X2: 1998-Q4 | Y2: 1999-Q1 | Z2: 1999-Q2 | AA2: 1999-Q3 | AB2: 1999-Q4 | AC2: 2000-Q1 | AD2: 2000-Q2 | AE2: 2000-Q3 | AF2: 2000-Q4 | AG2: 2001-Q1 | AH2: 2001-Q2 | AI2: 2001-Q3 | AJ2: 2001-Q4 | AK2: 2002-Q1 | AL2: 2002-Q2 | AM2: 2002-Q3 | AN2: 2002-Q4 | AO2: 2003-Q1 | AP2: 2003-Q2 | AQ2: 2003-Q3 | AR2: 2003-Q4 | AS2: 2004-Q1 | AT2: 2004-Q2 | AU2: 2004-Q3 | AV2: 2004-Q4 | AW2: 2005-Q1 | AX2: 2005-Q2 | AY2: 2005-Q3 | AZ2: 2005-Q4 | BA2: 2006-Q1 | BB2: 2006-Q2 | BC2: 2006-Q3 | BD2: 2006-Q4 | BE2: 2007-Q1 | BF2: 2007-Q2 | BG2: 2007-Q3 | BH2: 2007-Q4 | BI2: 2008-Q1 | BJ2: 2008-Q2 | BK2: 2008-Q3 | BL2: 2008-Q4 | BM2: 2009-Q1 | BN2: 2009-Q2 | BO2: 2009-Q3 | BP2: 2009-Q4 | BQ2: 2010-Q1 | BR2: 2010-Q2 | BS2: 2010-Q3 | BT2: 2010-Q4 | BU2: 2011-Q1 | BV2: 2011-Q2 | BW2: 2011-Q3 | BX2: 2011-Q4 | BY2: 2012-Q1 | BZ2: 2012-Q2 | CA2: 2012-Q3 | CB2: 2012-Q4 | CC2: 2013-Q1 | CD2: 2013-Q2 | CE2: 2013-Q3 | CF2: 2013-Q4 | CG2: 2014-Q1 | CH2: 2014-Q2 | CI2: 2014-Q3 | CJ2: 2014-Q4 | CK2: 2015-Q1 | CL2: 2015-Q2 | CM2: 2015-Q3 | CN2: 2015-Q4 | CO2: 2016-Q1 | CP2: 2016-Q2 | CQ2: 2016-Q3 | CR2: 2016-Q4 | CS2: 2017-Q1 | CT2: 2017-Q2 | CU2: 2017-Q3 | CV2: 2017-Q4 | CW2: 2018-Q1 | CX2: 2018-Q2 | CY2: 2018-Q3 | CZ2: 2018-Q4 | DA2: 2019-Q1 | DB2: 2019-Q2 | DC2: 2019-Q3 | DD2: 2019-Q4 | DE2: 2020-Q1 | DF2: 2020-Q2 | DG2: 2020-Q3 | DH2: 2020-Q4 | DI2: 2021-Q1 | DJ2: 2021-Q2 | DK2: 2021-Q3 | DL2: 2021-Q4 | DM2: 2022-Q1 | DN2: 2022-Q2 | DO2: 2022-Q3 | DP2: 2022-Q4 | DQ2: 2023-Q1 | DR2: 2023-Q2 | DS2: 2023-Q3 | DT2: 2023-Q4 | DU2: 2024-Q1 | DV2: 2024-Q2 | DW2: 2024-Q3 | DX2: 2024-Q4 | DY2: 2025-Q1 | DZ2: 2025-Q2 | EA2: 2025-Q3
A3: =Denmark!D12 -> -9.2795 | B3: =Denmark!E12 -> -8.616 | C3: =Denmark!F12 -> -0.8405 | D3: =Denmark!G12 -> 7.94 | E3: =Denmark!H12 -> 16.471 | F3: =Denmark!I12 -> 15.6385 | G3: =Denmark!J12 -> 9.7085 | H3: =Denmark!K12 -> 5.499 | ... EA3: =Denmark!ED12 -> 10.795
A4: =Denmark!D16 -> -6.2265 | B4: =Denmark!E16 -> -7.643 | C4: =Denmark!F16 -> -3.451 | D4: =Denmark!G16 -> 8.123 | E4: =Denmark!H16 -> 12.28 | F4: =Denmark!I16 -> 14.4345 | G4: =Denmark!J16 -> 8.139 | H4: =Denmark!K16 -> 1.813 | ... EA4: =Denmark!ED16 -> 6.8785
A5: =Denmark!D20 -> -5.2445 | B5: =Denmark!E20 -> -6.8945 | C5: =Denmark!F20 -> -0.4065 | D5: =Denmark!G20 -> 6.9825 | E5: =Denmark!H20 -> 13.9925 | F5: =Denmark!I20 -> 14.1105 | G5: =Denmark!J20 -> 8.478 | H5: =Denmark!K20 -> 3.1345 | ... EA5: =Denmark!ED20 -> 6.303
A6: =Denmark!D24 -> -8.179 | B6: =Denmark!E24 -> -6.9555 | C6: =Denmark!F24 -> -1.0685 | D6: =Denmark!G24 -> 6.051 | E6: =Denmark!H24 -> 16.2805 | F6: =Denmark!I24 -> 16.148 | G6: =Denmark!J24 -> 8.7585 | H6: =Denmark!K24 -> 3.3075 | ... EA6: =Denmark!ED24 -> 6.0955
A7: =Denmark!D28 -> -7.9105 | B7: =Denmark!E28 -> -7.4285 | C7: =Denmark!F28 -> 0.3635 | D7: =Denmark!G28 -> 6.4955 | E7: =Denmark!H28 -> 14.8855 | F7: =Denmark!I28 -> 16.094 | G7: =Denmark!J28 -> 8.6915 | H7: =Denmark!K28 -> 4.035 | ... EA7: =Denmark!ED28 -> -0.6
A11: Japan
A12: 1993-Q1 | B12: 1993-Q2 | C12: 1993-Q3 | D12: 1993-Q4 | E12: 1994-Q1 | F12: 1994-Q2 | G12: 1994-Q3 | H12: 1994-Q4 | I12: 1995-Q1 | J12: 1995-Q2 | K12: 1995-Q3 | L12: 1995-Q4 | M12: 1996-Q1 | N12: 1996-Q2 | O12: 1996-Q3 | P12: 1996-Q4 | Q12: 1997-Q1 | R12: 1997-Q2 | S12: 1997-Q3 | T12: 1997-Q4 | U12: 1998-Q1 | V12: 1998-Q2 | W12: 1998-Q3 | X12: 1998-Q4 | Y12: 1999-Q1 | Z12: 1999-Q2 | AA12: 1999-Q3 | AB12: 1999-Q4 | AC12: 2000-Q1 | AD12: 2000-Q2 | AE12: 2000-Q3 | AF12: 2000-Q4 | AG12: 2001-Q1 | AH12: 2001-Q2 | AI12: 2001-Q3 | AJ12: 2001-Q4 | AK12: 2002-Q1 | AL12: 2002-Q2 | AM12: 2002-Q3 | AN12: 2002-Q4 | AO12: 2003-Q1 | AP12: 2003-Q2 | AQ12: 2003-Q3 | AR12: 2003-Q4 | AS12: 2004-Q1 | AT12: 2004-Q2 | AU12: 2004-Q3 | AV12: 2004-Q4 | AW12: 2005-Q1 | AX12: 2005-Q2 | AY12: 2005-Q3 | AZ12: 2005-Q4 | BA12: 2006-Q1 | BB12: 2006-Q2 | BC12: 2006-Q3 | BD12: 2006-Q4 | BE12: 2007-Q1 | BF12: 2007-Q2 | BG12: 2007-Q3 | BH12: 2007-Q4 | BI12: 2008-Q1 | BJ12: 2008-Q2 | BK12: 2008-Q3 | BL12: 2008-Q4 | BM12: 2009-Q1 | BN12: 2009-Q2 | BO12: 2009-Q3 | BP12: 2009-Q4 | BQ12: 2010-Q1 | BR12: 2010-Q2 | BS12: 2010-Q3 | BT12: 2010-Q4 | BU12: 2011-Q1 | BV12: 2011-Q2 | BW12: 2011-Q3 | BX12: 2011-Q4 | BY12: 2012-Q1 | BZ12: 2012-Q2 | CA12: 2012-Q3 | CB12: 2012-Q4 | CC12: 2013-Q1 | CD12: 2013-Q2 | CE12: 2013-Q3 | CF12: 2013-Q4 | CG12: 2014-Q1 | CH12: 2014-Q2 | CI12: 2014-Q3 | CJ12: 2014-Q4 | CK12: 2015-Q1 | CL12: 2015-Q2 | CM12: 2015-Q3 | CN12: 2015-Q4 | CO12: 2016-Q1 | CP12: 2016-Q2 | CQ12: 2016-Q3 | CR12: 2016-Q4 | CS12: 2017-Q1 | CT12: 2017-Q2 | CU12: 2017-Q3 | CV12: 2017-Q4 | CW12: 2018-Q1 | CX12: 2018-Q2 | CY12: 2018-Q3 | CZ12: 2018-Q4 | DA12: 2019-Q1 | DB12: 2019-Q2 | DC12: 2019-Q3 | DD12: 2019-Q4 | DE12: 2020-Q1 | DF12: 2020-Q2 | DG12: 2020-Q3 | DH12: 2020-Q4 | DI12: 2021-Q1 | DJ12: 2021-Q2 | DK12: 2021-Q3 | DL12: 2021-Q4 | DM12: 2022-Q1 | DN12: 2022-Q2 | DO12: 2022-Q3 | DP12: 2022-Q4 | DQ12: 2023-Q1 | DR12: 2023-Q2 | DS12: 2023-Q3 | DT12: 2023-Q4 | DU12: 2024-Q1 | DV12: 2024-Q2 | DW12: 2024-Q3 | DX12: 2024-Q4 | DY12: 2025-Q1 | DZ12: 2025-Q2 | EA12: 2025-Q3
BN13: =Japan!H9 -> -6.6 | BO13: =Japan!I9 -> -4.3 | BP13: =Japan!J9 -> -4.1 | BQ13: =Japan!K9 -> -2.1 | BR13: =Japan!L9 -> 3.6 | BS13: =Japan!M9 -> -1.2 | BT13: =Japan!N9 -> -0.3 | BU13: =Japan!O9 -> -0.9 | ... EA13: =Japan!BU9 -> 5.4
BN14: =Japan!H15 -> -7.5 | BO14: =Japan!I15 -> -6 | BP14: =Japan!J15 -> -2 | BQ14: =Japan!K15 -> -1.9 | BR14: =Japan!L15 -> -1.6 | BS14: =Japan!M15 -> 0 | BT14: =Japan!N15 -> 0.8 | BU14: =Japan!O15 -> 0 | ... EA14: =Japan!BU15 -> 2.7
BN15: =Japan!H21 -> -10.1 | BO15: =Japan!I21 -> -6.6 | BP15: =Japan!J21 -> -2.7 | BQ15: =Japan!K21 -> 1.7 | BR15: =Japan!L21 -> 3.4 | BS15: =Japan!M21 -> 2.1 | BT15: =Japan!N21 -> 2.6 | BU15: =Japan!O21 -> 1.7 | ... EA15: =Japan!BU21 -> 6
BN16: =Japan!H27 -> -7.6 | BO16: =Japan!I27 -> -6.4 | BP16: =Japan!J27 -> -3.6 | BQ16: =Japan!K27 -> -4.7 | BR16: =Japan!L27 -> -5.4 | BS16: =Japan!M27 -> -4.9 | BT16: =Japan!N27 -> -3.3 | BU16: =Japan!O27 -> 1.5 | ... EA16: =Japan!BU27 -> -1
BN17: =Japan!H33 -> -7 | BO17: =Japan!I33 -> -6.6 | BP17: =Japan!J33 -> -5.7 | BQ17: =Japan!K33 -> -0.4 | BR17: =Japan!L33 -> -1.1 | BS17: =Japan!M33 -> -0.1 | BT17: =Japan!N33 -> 1.3 | BU17: =Japan!O33 -> -0.3 | ... EA17: =Japan!BU33 -> 1.7
BN18: =Japan!H39 -> -5.1 | BO18: =Japan!I39 -> -7 | BP18: =Japan!J39 -> -1.1 | BQ18: =Japan!K39 -> 3.6 | BR18: =Japan!L39 -> 2.4 | BS18: =Japan!M39 -> 3.9 | BT18: =Japan!N39 -> 5.6 | BU18: =Japan!O39 -> 1.6 | ... EA18: =Japan!BU39 -> -2.3
BN19: =Japan!H45 -> -7.2 | BO19: =Japan!I45 -> -6.6 | BP19: =Japan!J45 -> -1.9 | BQ19: =Japan!K45 -> -6.2 | BR19: =Japan!L45 -> -0.6 | BS19: =Japan!M45 -> -0.7 | BT19: =Japan!N45 -> -1.7 | BU19: =Japan!O45 -> -3 | ... EA19: =Japan!BU45 -> -2
BN20: =Japan!H51 -> -8.5 | BO20: =Japan!I51 -> -3.7 | BP20: =Japan!J51 -> -2.1 | BQ20: =Japan!K51 -> -1.6 | BR20: =Japan!L51 -> 3.4 | BS20: =Japan!M51 -> 3 | BT20: =Japan!N51 -> 1.6 | BU20: =Japan!O51 -> 4.1 | ... EA20: =Japan!BU51 -> 5.5
A24: Poland
A25: 1993-Q1 | B25: 1993-Q2 | C25: 1993-Q3 | D25: 1993-Q4 | E25: 1994-Q1 | F25: 1994-Q2 | G25: 1994-Q3 | H25: 1994-Q4 | I25: 1995-Q1 | J25: 1995-Q2 | K25: 1995-Q3 | L25: 1995-Q4 | M25: 1996-Q1 | N25: 1996-Q2 | O25: 1996-Q3 | P25: 1996-Q4 | Q25: 1997-Q1 | R25: 1997-Q2 | S25: 1997-Q3 | T25: 1997-Q4 | U25: 1998-Q1 | V25: 1998-Q2 | W25: 1998-Q3 | X25: 1998-Q4 | Y25: 1999-Q1 | Z25: 1999-Q2 | AA25: 1999-Q3 | AB25: 1999-Q4 | AC25: 2000-Q1 | AD25: 2000-Q2 | AE25: 2000-Q3 | AF25: 2000-Q4 | AG25: 2001-Q1 | AH25: 2001-Q2 | AI25: 2001-Q3 | AJ25: 2001-Q4 | AK25: 2002-Q1 | AL25: 2002-Q2 | AM25: 2002-Q3 | AN25: 2002-Q4 | AO25: 2003-Q1 | AP25: 2003-Q2 | AQ25: 2003-Q3 | AR25: 2003-Q4 | AS25: 2004-Q1 | AT25: 2004-Q2 | AU25: 2004-Q3 | AV25: 2004-Q4 | AW25: 2005-Q1 | AX25: 2005-Q2 | AY25: 2005-Q3 | AZ25: 2005-Q4 | BA25: 2006-Q1 | BB25: 2006-Q2 | BC25: 2006-Q3 | BD25: 2006-Q4 | BE25: 2007-Q1 | BF25: 2007-Q2 | BG25: 2007-Q3 | BH25: 2007-Q4 | BI25: 2008-Q1 | BJ25: 2008-Q2 | BK25: 2008-Q3 | BL25: 2008-Q4 | BM25: 2009-Q1 | BN25: 2009-Q2 | BO25: 2009-Q3 | BP25: 2009-Q4 | BQ25: 2010-Q1 | BR25: 2010-Q2 | BS25: 2010-Q3 | BT25: 2010-Q4 | BU25: 2011-Q1 | BV25: 2011-Q2 | BW25: 2011-Q3 | BX25: 2011-Q4 | BY25: 2012-Q1 | BZ25: 2012-Q2 | CA25: 2012-Q3 | CB25: 2012-Q4 | CC25: 2013-Q1 | CD25: 2013-Q2 | CE25: 2013-Q3 | CF25: 2013-Q4 | CG25: 2014-Q1 | CH25: 2014-Q2 | CI25: 2014-Q3 | CJ25: 2014-Q4 | CK25: 2015-Q1 | CL25: 2015-Q2 | CM25: 2015-Q3 | CN25: 2015-Q4 | CO25: 2016-Q1 | CP25: 2016-Q2 | CQ25: 2016-Q3 | CR25: 2016-Q4 | CS25: 2017-Q1 | CT25: 2017-Q2 | CU25: 2017-Q3 | CV25: 2017-Q4 | CW25: 2018-Q1 | CX25: 2018-Q2 | CY25: 2018-Q3 | CZ25: 2018-Q4 | DA25: 2019-Q1 | DB25: 2019-Q2 | DC25: 2019-Q3 | DD25: 2019-Q4 | DE25: 2020-Q1 | DF25: 2020-Q2 | DG25: 2020-Q3 | DH25: 2020-Q4 | DI25: 2021-Q1 | DJ25: 2021-Q2 | DK25: 2021-Q3 | DL25: 2021-Q4 | DM25: 2022-Q1 | DN25: 2022-Q2 | DO25: 2022-Q3 | DP25: 2022-Q4 | DQ25: 2023-Q1 | DR25: 2023-Q2 | DS25: 2023-Q3 | DT25: 2023-Q4 | DU25: 2024-Q1 | DV25: 2024-Q2 | DW25: 2024-Q3 | DX25: 2024-Q4 | DY25: 2025-Q1 | DZ25: 2025-Q2 | EA25: 2025-Q3
BU26: =Poland!D9 -> 4.2 | BV26: =Poland!E9 -> -1.3 | BW26: =Poland!F9 -> 0.3 | BX26: =Poland!G9 -> -0.3 | BY26: =Poland!H9 -> -1.7 | BZ26: =Poland!I9 -> 0.3 | CA26: =Poland!J9 -> -5.6 | CB26: =Poland!K9 -> -6 | ... EA26: =Poland!BJ9 -> 2.4
BU27: =Poland!D10 -> 4.5 | BV27: =Poland!E10 -> 3.4 | BW27: =Poland!F10 -> 1.8 | BX27: =Poland!G10 -> 3.4 | BY27: =Poland!H10 -> -1.5 | BZ27: =Poland!I10 -> -1.8 | CA27: =Poland!J10 -> -5.7 | CB27: =Poland!K10 -> -4.9 | ... EA27: =Poland!BJ10 -> 2.9
BU28: =Poland!D11 -> -0.3 | BV28: =Poland!E11 -> 0.7 | BW28: =Poland!F11 -> -4.2 | BX28: =Poland!G11 -> 1 | BY28: =Poland!H11 -> 0.1 | BZ28: =Poland!I11 -> -2.8 | CA28: =Poland!J11 -> -2.9 | CB28: =Poland!K11 -> -5.8 | ... EA28: =Poland!BJ11 -> 5.9
BU29: =Poland!D12 -> -0.9 | BV29: =Poland!E12 -> -8.2 | BW29: =Poland!F12 -> -3.7 | BX29: =Poland!G12 -> -7.6 | BY29: =Poland!H12 -> -5 | BZ29: =Poland!I12 -> -0.5 | CA29: =Poland!J12 -> -5.7 | CB29: =Poland!K12 -> -3.1 | ... EA29: =Poland!BJ12 -> 3.7
BU30: =Poland!D13 -> 1.5 | BV30: =Poland!E13 -> 2.3 | BW30: =Poland!F13 -> 0.8 | BX30: =Poland!G13 -> 3.1 | BY30: =Poland!H13 -> -2 | BZ30: =Poland!I13 -> -1.5 | CA30: =Poland!J13 -> -3.1 | CB30: =Poland!K13 -> -3.4 | ... EA30: =Poland!BJ13 -> 3.9
BU31: =Poland!D14 -> 6 | BV31: =Poland!E14 -> 2.3 | BW31: =Poland!F14 -> 0.9 | BX31: =Poland!G14 -> -1.6 | BY31: =Poland!H14 -> -4.4 | BZ31: =Poland!I14 -> -5.2 | CA31: =Poland!J14 -> -5.4 | CB31: =Poland!K14 -> -5.8 | ... EA31: =Poland!BJ14 -> 4.8
BU32: =Poland!D15 -> 1.5 | BV32: =Poland!E15 -> 2.3 | BW32: =Poland!F15 -> 2.3 | BX32: =Poland!G15 -> 2.2 | BY32: =Poland!H15 -> -1.7 | BZ32: =Poland!I15 -> -3.5 | CA32: =Poland!J15 -> -1.7 | CB32: =Poland!K15 -> -4.7 | ... EA32: =Poland!BJ15 -> 4.2
BU33: =Poland!D16 -> 4.3 | BV33: =Poland!E16 -> 5.1 | BW33: =Poland!F16 -> 1.2 | BX33: =Poland!G16 -> 6.1 | BY33: =Poland!H16 -> -3 | BZ33: =Poland!I16 -> -1.8 | CA33: =Poland!J16 -> -2.6 | CB33: =Poland!K16 -> -1.7 | ... EA33: =Poland!BJ16 -> 3.7
BU34: =Poland!D17 -> 0.7 | BV34: =Poland!E17 -> 4.5 | BW34: =Poland!F17 -> -4.5 | BX34: =Poland!G17 -> -1.7 | BY34: =Poland!H17 -> -5.4 | BZ34: =Poland!I17 -> -7.1 | CA34: =Poland!J17 -> -4.8 | CB34: =Poland!K17 -> -3 | ... EA34: =Poland!BJ17 -> 4.3
BU35: =Poland!D18 -> -5.7 | BV35: =Poland!E18 -> 0.8 | BW35: =Poland!F18 -> -2.5 | BX35: =Poland!G18 -> -6.1 | BY35: =Poland!H18 -> 3.7 | BZ35: =Poland!I18 -> -1.3 | CA35: =Poland!J18 -> 3.5 | CB35: =Poland!K18 -> 0.3 | ... EA35: =Poland!BJ18 -> 5.2
BU36: =Poland!D19 -> 5.4 | BV36: =Poland!E19 -> 3.9 | BW36: =Poland!F19 -> 1.1 | BX36: =Poland!G19 -> -0.7 | BY36: =Poland!H19 -> -1.7 | BZ36: =Poland!I19 -> -4.1 | CA36: =Poland!J19 -> -2.5 | CB36: =Poland!K19 -> -2.2 | ... EA36: =Poland!BJ19 -> 3.3
BU37: =Poland!D20 -> 4.4 | BV37: =Poland!E20 -> -2.9 | BW37: =Poland!F20 -> -3.9 | BX37: =Poland!G20 -> 3.2 | BY37: =Poland!H20 -> 1.5 | BZ37: =Poland!I20 -> 1.5 | CA37: =Poland!J20 -> 1.1 | CB37: =Poland!K20 -> -3.4 | ... EA37: =Poland!BJ20 -> 3.3
... BU41: =Poland!D24 -> -0.1 | BV41: =Poland!E24 -> -1.5 | BW41: =Poland!F24 -> -1.1 | BX41: =Poland!G24 -> -1.8 | BY41: =Poland!H24 -> -4.3 | BZ41: =Poland!I24 -> -5.7 | CA41: =Poland!J24 -> -5.7 | CB41: =Poland!K24 -> -6.1 | ... EA41: =Poland!BJ24 -> 3.5
A43: Spain
A44: 1993-Q1 | B44: 1993-Q2 | C44: 1993-Q3 | D44: 1993-Q4 | E44: 1994-Q1 | F44: 1994-Q2 | G44: 1994-Q3 | H44: 1994-Q4 | I44: 1995-Q1 | J44: 1995-Q2 | K44: 1995-Q3 | L44: 1995-Q4 | M44: 1996-Q1 | N44: 1996-Q2 | O44: 1996-Q3 | P44: 1996-Q4 | Q44: 1997-Q1 | R44: 1997-Q2 | S44: 1997-Q3 | T44: 1997-Q4 | U44: 1998-Q1 | V44: 1998-Q2 | W44: 1998-Q3 | X44: 1998-Q4 | Y44: 1999-Q1 | Z44: 1999-Q2 | AA44: 1999-Q3 | AB44: 1999-Q4 | AC44: 2000-Q1 | AD44: 2000-Q2 | AE44: 2000-Q3 | AF44: 2000-Q4 | AG44: 2001-Q1 | AH44: 2001-Q2 | AI44: 2001-Q3 | AJ44: 2001-Q4 | AK44: 2002-Q1 | AL44: 2002-Q2 | AM44: 2002-Q3 | AN44: 2002-Q4 | AO44: 2003-Q1 | AP44: 2003-Q2 | AQ44: 2003-Q3 | AR44: 2003-Q4 | AS44: 2004-Q1 | AT44: 2004-Q2 | AU44: 2004-Q3 | AV44: 2004-Q4 | AW44: 2005-Q1 | AX44: 2005-Q2 | AY44: 2005-Q3 | AZ44: 2005-Q4 | BA44: 2006-Q1 | BB44: 2006-Q2 | BC44: 2006-Q3 | BD44: 2006-Q4 | BE44: 2007-Q1 | BF44: 2007-Q2 | BG44: 2007-Q3 | BH44: 2007-Q4 | BI44: 2008-Q1 | BJ44: 2008-Q2 | BK44: 2008-Q3 | BL44: 2008-Q4 | BM44: 2009-Q1 | BN44: 2009-Q2 | BO44: 2009-Q3 | BP44: 2009-Q4 | BQ44: 2010-Q1 | BR44: 2010-Q2 | BS44: 2010-Q3 | BT44: 2010-Q4 | BU44: 2011-Q1 | BV44: 2011-Q2 | BW44: 2011-Q3 | BX44: 2011-Q4 | BY44: 2012-Q1 | BZ44: 2012-Q2 | CA44: 2012-Q3 | CB44: 2012-Q4 | CC44: 2013-Q1 | CD44: 2013-Q2 | CE44: 2013-Q3 | CF44: 2013-Q4 | CG44: 2014-Q1 | CH44: 2014-Q2 | CI44: 2014-Q3 | CJ44: 2014-Q4 | CK44: 2015-Q1 | CL44: 2015-Q2 | CM44: 2015-Q3 | CN44: 2015-Q4 | CO44: 2016-Q1 | CP44: 2016-Q2 | CQ44: 2016-Q3 | CR44: 2016-Q4 | CS44: 2017-Q1 | CT44: 2017-Q2 | CU44: 2017-Q3 | CV44: 2017-Q4 | CW44: 2018-Q1 | CX44: 2018-Q2 | CY44: 2018-Q3 | CZ44: 2018-Q4 | DA44: 2019-Q1 | DB44: 2019-Q2 | DC44: 2019-Q3 | DD44: 2019-Q4 | DE44: 2020-Q1 | DF44: 2020-Q2 | DG44: 2020-Q3 | DH44: 2020-Q4 | DI44: 2021-Q1 | DJ44: 2021-Q2 | DK44: 2021-Q3 | DL44: 2021-Q4 | DM44: 2022-Q1 | DN44: 2022-Q2 | DO44: 2022-Q3 | DP44: 2022-Q4 | DQ44: 2023-Q1 | DR44: 2023-Q2 | DS44: 2023-Q3 | DT44: 2023-Q4 | DU44: 2024-Q1 | DV44: 2024-Q2 | DW44: 2024-Q3 | DX44: 2024-Q4 | DY44: 2025-Q1 | DZ44: 2025-Q2 | EA44: 2025-Q3
BE45: =Spain!D9 -> -6.768 | BF45: =Spain!E9 -> -4.544 | BG45: =Spain!F9 -> -2.329 | BH45: =Spain!G9 -> 0.41 | BI45: =Spain!H9 -> 7.26 | BJ45: =Spain!I9 -> 4.76 | BK45: =Spain!J9 -> 2.384 | BL45: =Spain!K9 -> -0.409 | ... EA45: =Spain!BZ9 -> 13.383
BE46: =Spain!D10 -> -5.679 | BF46: =Spain!E10 -> -1.479 | BG46: =Spain!F10 -> 0.919 | BH46: =Spain!G10 -> 1.652 | BI46: =Spain!H10 -> 6.021 | BJ46: =Spain!I10 -> 1.501 | BK46: =Spain!J10 -> -0.911 | BL46: =Spain!K10 -> -1.625 | ... EA46: =Spain!BZ10 -> 13.491
BE47: =Spain!D11 -> -5.145 | BF47: =Spain!E11 -> -2.297 | BG47: =Spain!F11 -> 0.135 | BH47: =Spain!G11 -> 2.649 | BI47: =Spain!H11 -> 5.425 | BJ47: =Spain!I11 -> 2.351 | BK47: =Spain!J11 -> -0.135 | BL47: =Spain!K11 -> -2.58 | ... EA47: =Spain!BZ11 -> 12.599
BE48: =Spain!D12 -> -1.489 | BF48: =Spain!E12 -> 1.253 | BG48: =Spain!F12 -> 6.766 | BH48: =Spain!G12 -> 8.74 | BI48: =Spain!H12 -> 1.511 | BJ48: =Spain!I12 -> -1.237 | BK48: =Spain!J12 -> -6.337 | BL48: =Spain!K12 -> -8.038 | ... EA48: =Spain!BZ12 -> 11.641
BE49: =Spain!D13 -> -0.923 | BF49: =Spain!E13 -> -0.598 | BG49: =Spain!F13 -> 5.551 | BH49: =Spain!G13 -> 5.982 | BI49: =Spain!H13 -> 0.932 | BJ49: =Spain!I13 -> 0.602 | BK49: =Spain!J13 -> -5.259 | BL49: =Spain!K13 -> -5.644 | ... EA49: =Spain!BZ13 -> 10.906
BE50: =Spain!D14 -> -6.069 | BF50: =Spain!E14 -> -1.962 | BG50: =Spain!F14 -> 1.891 | BH50: =Spain!G14 -> 3.966 | BI50: =Spain!H14 -> 6.461 | BJ50: =Spain!I14 -> 2.002 | BK50: =Spain!J14 -> -1.856 | BL50: =Spain!K14 -> -3.815 | ... EA50: =Spain!BZ14 -> 14.122
...

Sheet Spain
B1: National and regional house price indices
B2: Reference area type: Large regions
B3: Frequency of observation: Quarterly
B4: Measure: House price index
B5: Combined unit of measure: Percent per annum, Growth rate, over 1 year
B7: Time period | C7: Time period | D7: 2007-Q1 | E7: 2007-Q2 | F7: 2007-Q3 | G7: 2007-Q4 | H7: 2008-Q1 | I7: 2008-Q2 | J7: 2008-Q3 | K7: 2008-Q4 | L7: 2009-Q1 | M7: 2009-Q2 | N7: 2009-Q3 | O7: 2009-Q4 | P7: 2010-Q1 | Q7: 2010-Q2 | R7: 2010-Q3 | S7: 2010-Q4 | T7: 2011-Q1 | U7: 2011-Q2 | V7: 2011-Q3 | W7: 2011-Q4 | X7: 2012-Q1 | Y7: 2012-Q2 | Z7: 2012-Q3 | AA7: 2012-Q4 | AB7: 2013-Q1 | AC7: 2013-Q2 | AD7: 2013-Q3 | AE7: 2013-Q4 | AF7: 2014-Q1 | AG7: 2014-Q2 | AH7: 2014-Q3 | AI7: 2014-Q4 | AJ7: 2015-Q1 | AK7: 2015-Q2 | AL7: 2015-Q3 | AM7: 2015-Q4 | AN7: 2016-Q1 | AO7: 2016-Q2 | AP7: 2016-Q3 | AQ7: 2016-Q4 | AR7: 2017-Q1 | AS7: 2017-Q2 | AT7: 2017-Q3 | AU7: 2017-Q4 | AV7: 2018-Q1 | AW7: 2018-Q2 | AX7: 2018-Q3 | AY7: 2018-Q4 | AZ7: 2019-Q1 | BA7: 2019-Q2 | BB7: 2019-Q3 | BC7: 2019-Q4 | BD7: 2020-Q1 | BE7: 2020-Q2 | BF7: 2020-Q3 | BG7: 2020-Q4 | BH7: 2021-Q1 | BI7: 2021-Q2 | BJ7: 2021-Q3 | BK7: 2021-Q4 | BL7: 2022-Q1 | BM7: 2022-Q2 | BN7: 2022-Q3 | BO7: 2022-Q4 | BP7: 2023-Q1 | BQ7: 2023-Q2 | BR7: 2023-Q3 | BS7: 2023-Q4 | BT7: 2024-Q1 | BU7: 2024-Q2 | BV7: 2024-Q3 | BW7: 2024-Q4 | BX7: 2025-Q1 | BY7: 2025-Q2 | BZ7: 2025-Q3
B8: Reference area
B9: Galicia | D9: -6.768 | E9: -4.544 | F9: -2.329 | G9: 0.41 | H9: 7.26 | I9: 4.76 | J9: 2.384 | K9: -0.409 | L9: -0.543 | M9: -0.849 | N9: -2.033 | O9: -1.47 | P9: -2.418 | Q9: -0.779 | R9: -3.238 | S9: -1.385 | T9: -2.964 | U9: -5.464 | V9: -3.961 | W9: -7.904 | X9: -11.147 | Y9: -12.73 | Z9: -15.346 | AA9: -12.623 | AB9: -13.44 | AC9: -12.956 | AD9: -7.137 | AE9: -10.862 | AF9: -3.719 | AG9: 0.067 | AH9: -1.974 | AI9: 1.008 | AJ9: 0.52 | AK9: 0.799 | AL9: 2.466 | AM9: 1.664 | AN9: 3.296 | AO9: 1.232 | AP9: 1.263 | AQ9: 2.074 | AR9: 1.322 | AS9: 0.959 | AT9: 1.73 | AU9: 2.887 | AV9: 3.202 | AW9: 3.919 | AX9: 4.068 | AY9: 4.06 | AZ9: 3.558 | BA9: 4.847 | BB9: 3.749 | BC9: 3.917 | BD9: 3.277 | BE9: 2.67 | BF9: 1.921 | BG9: 1.162 | BH9: 2.245 | BI9: 3.495 | BJ9: 5.788 | BK9: 6.832 | BL9: 8.285 | BM9: 7.674 | BN9: 6.08 | BO9: 4.478 | BP9: 3.359 | BQ9: 3.118 | BR9: 4.559 | BS9: 3.431 | BT9: 5.109 | BU9: 6.718 | BV9: 7.35 | BW9: 10.547 | BX9: 11.219 | BY9: 12.747 | BZ9: 13.383
B10: Asturias | D10: -5.679 | E10: -1.479 | F10: 0.919 | G10: 1.652 | H10: 6.021 | I10: 1.501 | J10: -0.911 | K10: -1.625 | L10: -1.768 | M10: -0.935 | N10: -0.493 | O10: -0.497 | P10: -1.602 | Q10: 0.22 | R10: -3.396 | S10: -1.043 | T10: -2.625 | U10: -6.205 | V10: -3.653 | W10: -10.453 | X10: -13.904 | Y10: -14.293 | Z10: -17.485 | AA10: -12.389 | AB10: -14.132 | AC10: -12.65 | AD10: -9.669 | AE10: -11.468 | AF10: -5.028 | AG10: -1.988 | AH10: -1.514 | AI10: -0.33 | AJ10: 0.324 | AK10: 0.941 | AL10: 3.465 | AM10: 1.301 | AN10: 3.105 | AO10: 0.71 | AP10: -0.012 | AQ10: 1.948 | AR10: 1.401 | AS10: -0.261 | AT10: 0.849 | AU10: 2.417 | AV10: 2.152 | AW10: 4.103 | AX10: 4.389 | AY10: 3.351 | AZ10: 3.787 | BA10: 5.116 | BB10: 3.534 | BC10: 4.296 | BD10: 4.363 | BE10: 3.815 | BF10: 2.723 | BG10: 1.855 | BH10: 2.178 | BI10: 3.635 | BJ10: 4.611 | BK10: 6.155 | BL10: 7.27 | BM10: 6.595 | BN10: 6.408 | BO10: 4.62 | BP10: 3.594 | BQ10: 2.852 | BR10: 5.032 | BS10: 3.471 | BT10: 5.115 | BU10: 7.373 | BV10: 6.882 | BW10: 11.734 | BX10: 13.065 | BY10: 13.536 | BZ10: 13.491
B11: Cantabria | D11: -5.145 | E11: -2.297 | F11: 0.135 | G11: 2.649 | H11: 5.425 | I11: 2.351 | J11: -0.135 | K11: -2.58 | L11: -7.208 | M11: -7.375 | N11: -6.584 | O11: -6.016 | P11: -5.913 | Q11: -4.273 | R11: -6.698 | S11: -7.16 | T11: -6.093 | U11: -9.189 | V11: -10.259 | W11: -11.586 | X11: -13.104 | Y11: -15.015 | Z11: -15.674 | AA11: -12.702 | AB11: -14.577 | AC11: -11.223 | AD11: -5.35 | AE11: -4.563 | AF11: 1.407 | AG11: 1.778 | AH11: 1.963 | AI11: 1.755 | AJ11: -0.334 | AK11: 5.07 | AL11: 4.776 | AM11: 1.97 | AN11: 5.14 | AO11: 2.119 | AP11: 0.734 | AQ11: 2.347 | AR11: 2.963 | AS11: 4.123 | AT11: 4.588 | AU11: 4.433 | AV11: 5.74 | AW11: 5.797 | AX11: 5.674 | AY11: 6.238 | AZ11: 5.697 | BA11: 2.226 | BB11: 2.368 | BC11: 2.148 | BD11: 0.971 | BE11: 1.289 | BF11: 1.378 | BG11: 1.192 | BH11: 2.045 | BI11: 5.322 | BJ11: 6.876 | BK11: 7.699 | BL11: 10.972 | BM11: 9.942 | BN11: 9.335 | BO11: 8.581 | BP11: 5.585 | BQ11: 4.75 | BR11: 5.922 | BS11: 4.338 | BT11: 6.807 | BU11: 8.644 | BV11: 8.862 | BW11: 11.763 | BX11: 10.212 | BY11: 10.818 | BZ11: 12.599
B12: Basque Country | D12: -1.489 | E12: 1.253 | F12: 6.766 | G12: 8.74 | H12: 1.511 | I12: -1.237 | J12: -6.337 | K12: -8.038 | L12: -10.805 | M12: -12.603 | N12: -10.437 | O12: -7.056 | P12: -3.931 | Q12: -0.525 | R12: -0.616 | S12: -1.373 | T12: -3.195 | U12: -6.733 | V12: -8.681 | W12: -12.18 | X12: -16.16 | Y12: -15.596 | Z12: -15.32 | AA12: -13.254 | AB12: -12.946 | AC12: -9.808 | AD12: -4.983 | AE12: -5.339 | AF12: 1.384 | AG12: -1.391 | AH12: -1.909 | AI12: -0.019 | AJ12: -0.678 | AK12: 1.894 | AL12: 1.015 | AM12: 1.655 | AN12: 2.849 | AO12: 2.777 | AP12: 3.524 | AQ12: 1.16 | AR12: 3.283 | AS12: 4.545 | AT12: 5.786 | AU12: 7.102 | AV12: 6.112 | AW12: 5.784 | AX12: 4.822 | AY12: 5.035 | AZ12: 5.778 | BA12: 3.857 | BB12: 4.829 | BC12: 2.949 | BD12: 3.392 | BE12: 1.618 | BF12: 1.856 | BG12: 2.164 | BH12: 0.198 | BI12: 2.554 | BJ12: 1.355 | BK12: 4.227 | BL12: 6.25 | BM12: 6.496 | BN12: 7.802 | BO12: 4.918 | BP12: 3.082 | BQ12: 3.032 | BR12: 3.811 | BS12: 3.875 | BT12: 6.385 | BU12: 8.458 | BV12: 8.397 | BW12: 10.683 | BX12: 12.41 | BY12: 12.402 | BZ12: 11.641
B13: Navarra | D13: -0.923 | E13: -0.598 | F13: 5.551 | G13: 5.982 | H13: 0.932 | I13: 0.602 | J13: -5.259 | K13: -5.644 | L13: -10.114 | M13: -11.333 | N13: -10.133 | O13: -8.306 | P13: -6.683 | Q13: -6.153 | R13: -6.479 | S13: -5.851 | T13: -6.361 | U13: -7.601 | V13: -5.874 | W13: -10.902 | X13: -15.597 | Y13: -14.458 | Z13: -14.832 | AA13: -11.015 | AB13: -10.232 | AC13: -11.116 | AD13: -10.947 | AE13: -13.171 | AF13: -8.639 | AG13: -6.062 | AH13: -6.945 | AI13: -4.159 | AJ13: -0.877 | AK13: 0.177 | AL13: 1.39 | AM13: 1.77 | AN13: 2.498 | AO13: 0.137 | AP13: 2.17 | AQ13: 1.931 | AR13: 1.951 | AS13: 2.646 | AT13: 2.148 | AU13: 2.141 | AV13: 2.14 | AW13: 3.454 | AX13: 4.302 | AY13: 4.025 | AZ13: 4.938 | BA13: 3.895 | BB13: 3.069 | BC13: 3.223 | BD13: 3.218 | BE13: 1.213 | BF13: 1.735 | BG13: 0.585 | BH13: 0.231 | BI13: 2.575 | BJ13: 3.277 | BK13: 5.213 | BL13: 7.755 | BM13: 7.267 | BN13: 6.794 | BO13: 7.214 | BP13: 5.758 | BQ13: 5.639 | BR13: 7.625 | BS13: 4.674 | BT13: 7.627 | BU13: 10.304 | BV13: 10.714 | BW13: 12.906 | BX13: 11.437 | BY13: 12.037 | BZ13: 10.906
B14: La Rioja | D14: -6.069 | E14: -1.962 | F14: 1.891 | G14: 3.966 | H14: 6.461 | I14: 2.002 | J14: -1.856 | K14: -3.815 | L14: -8.014 | M14: -6.45 | N14: -4.151 | O14: -3.064 | P14: -2.943 | Q14: -1.697 | R14: -4.264 | S14: -6.219 | T14: -7.81 | U14: -10.912 | V14: -11.268 | W14: -14.242 | X14: -12.725 | Y14: -15.212 | Z14: -16.53 | AA14: -13.801 | AB14: -18.007 | AC14: -15.012 | AD14: -9.507 | AE14: -11.645 | AF14: -3.745 | AG14: -1.721 | AH14: -3.47 | AI14: 0.217 | AJ14: -1.538 | AK14: 1.195 | AL14: 0.855 | AM14: 1.547 | AN14: 3.811 | AO14: 1.528 | AP14: 2.224 | AQ14: 0.349 | AR14: 2.117 | AS14: 1.414 | AT14: 1.014 | AU14: 3.621 | AV14: 3.217 | AW14: 4.311 | AX14: 6.668 | AY14: 5.473 | AZ14: 6.24 | BA14: 6.207 | BB14: 4.401 | BC14: 4.662 | BD14: 3.185 | BE14: 2.174 | BF14: 1.192 | BG14: 1.021 | BH14: 1.466 | BI14: 2.312 | BJ14: 5.124 | BK14: 5.267 | BL14: 7.312 | BM14: 7.854 | BN14: 8.051 | BO14: 5.411 | BP14: 2.786 | BQ14: 2.625 | BR14: 1.921 | BS14: 3.926 | BT14: 7.118 | BU14: 8.609 | BV14: 9.189 | BW14: 11.877 | BX14: 13.247 | BY14: 13.744 | BZ14: 14.122
B15: Aragon | D15: -0.126 | E15: 0.173 | F15: 5.237 | G15: 7.179 | H15: 0.126 | I15: -0.173 | J15: -4.976 | K15: -6.698 | L15: -9.714 | M15: -10.011 | N15: -8.505 | O15: -6.8 | P15: -6.225 | Q15: -5.249 | R15: -5.911 | S15: -4.325 | T15: -6.212 | U15: -7.485 | V15: -6.654 | W15: -12.499 | X15: -14.875 | Y15: -14.532 | Z15: -16.236 | AA15: -11.811 | AB15: -13.163 | AC15: -13.974 | AD15: -11.144 | AE15: -12.46 | AF15: -4.889 | AG15: -2.279 | AH15: -2.002 | AI15: 0.064 | AJ15: 0.493 | AK15: 1.322 | AL15: 0.92 | AM15: 0.658 | AN15: 1.929 | AO15: 1.328 | AP15: 1.998 | AQ15: 2.335 | AR15: 3.743 | AS15: 1.641 | AT15: 2.858 | AU15: 3.132 | AV15: 3.075 | AW15: 4.501 | AX15: 5.476 | AY15: 6.203 | AZ15: 6.414 | BA15: 6.676 | BB15: 5.757 | BC15: 5.492 | BD15: 3.634 | BE15: 3.027 | BF15: 2.5 | BG15: 1.091 | BH15: 1.898 | BI15: 2.471 | BJ15: 4.458 | BK15: 6.329 | BL15: 7.697 | BM15: 7.542 | BN15: 6.182 | BO15: 4.289 | BP15: 3.183 | BQ15: 3.41 | BR15: 4.725 | BS15: 4.284 | BT15: 7.018 | BU15: 9.853 | BV15: 10.31 | BW15: 13.348 | BX15: 13.244 | BY15: 13.702 | BZ15: 14.583
B16: Madrid | D16: 2.827 | E16: 5.01 | F16: 7.542 | G16: 8.831 | H16: -2.749 | I16: -4.771 | J16: -7.013 | K16: -8.115 | L16: -11.184 | M16: -12.389 | N16: -11 | O16: -6.591 | P16: -2.292 | Q16: 1.359 | R16: 0.878 | S16: 1.679 | T16: -3.051 | U16: -7.077 | V16: -8.856 | W16: -15.679 | X16: -14.247 | Y16: -16.011 | Z16: -17.903 | AA16: -13.068 | AB16: -16.755 | AC16: -13.189 | AD16: -8.187 | AE16: -6.484 | AF16: 1.86 | AG16: 2.691 | AH16: 2.821 | AI16: 2.902 | AJ16: 2.312 | AK16: 6.351 | AL16: 6.923 | AM16: 7.318 | AN16: 9.742 | AO16: 7.755 | AP16: 7.812 | AQ16: 9.016 | AR16: 10.644 | AS16: 10.869 | AT16: 12.348 | AU16: 11.912 | AV16: 10.154 | AW16: 10.114 | AX16: 10.888 | AY16: 9.579 | AZ16: 9.714 | BA16: 6.459 | BB16: 4.604 | BC16: 2.934 | BD16: 2.514 | BE16: 1.658 | BF16: 1.214 | BG16: 1.474 | BH16: -0.029 | BI16: 1.9 | BJ16: 2.837 | BK16: 5.476 | BL16: 7.46 | BM16: 7.275 | BN16: 7.615 | BO16: 4.945 | BP16: 3.065 | BQ16: 4.078 | BR16: 4.103 | BS16: 4.463 | BT16: 5.883 | BU16: 7.182 | BV16: 7.24 | BW16: 10.323 | BX16: 11.637 | BY16: 13.265 | BZ16: 14.223
B17: Castile and León | D17: -6.894 | E17: -3.531 | F17: -0.312 | G17: 2.576 | H17: 7.404 | I17: 3.661 | J17: 0.313 | K17: -2.511 | L17: -3.324 | M17: -2.387 | N17: -2.477 | O17: -2.528 | P17: -4.233 | Q17: -1.882 | R17: -3.55 | S17: -1.339 | T17: -3.491 | U17: -6.046 | V17: -4.793 | W17: -10.478 | X17: -10.506 | Y17: -14.036 | Z17: -15.923 | AA17: -12.389 | AB17: -16.639 | AC17: -14.777 | AD17: -11.596 | AE17: -13.216 | AF17: -5.632 | AG17: -1.903 | AH17: -2.785 | AI17: 0.833 | AJ17: 0.848 | AK17: 1.428 | AL17: 1.747 | AM17: 0.937 | AN17: 1.732 | AO17: 0.549 | AP17: 1.186 | AQ17: 0.774 | AR17: 2.087 | AS17: 1.124 | AT17: 1.06 | AU17: 2.283 | AV17: 2.189 | AW17: 3.776 | AX17: 5.693 | AY17: 4.731 | AZ17: 4.946 | BA17: 5.325 | BB17: 4.064 | BC17: 4.992 | BD17: 2.926 | BE17: 2.956 | BF17: 2.227 | BG17: 1.326 | BH17: 1.983 | BI17: 2.602 | BJ17: 4.232 | BK17: 5.381 | BL17: 7.244 | BM17: 6.412 | BN17: 6.559 | BO17: 4.062 | BP17: 2.501 | BQ17: 2.842 | BR17: 2.452 | BS17: 3.475 | BT17: 5.904 | BU17: 6.871 | BV17: 7.988 | BW17: 10.567 | BX17: 12.434 | BY17: 13.573 | BZ17: 14.422
B18: Castile-La Mancha | D18: -4.778 | E18: -3.373 | F18: -1.336 | G18: 1.568 | H18: 5.018 | I18: 3.49 | J18: 1.354 | K18: -1.544 | L18: -2.452 | M18: -3.508 | N18: -3.839 | O18: -2.108 | P18: -1.757 | Q18: 0.441 | R18: -2.378 | S18: -0.822 | T18: -4.371 | U18: -7.298 | V18: -5.147 | W18: -8.845 | X18: -9.794 | Y18: -11.57 | Z18: -13.766 | AA18: -11.194 | AB18: -16.467 | AC18: -16.119 | AD18: -12.886 | AE18: -14.925 | AF18: -6.043 | AG18: -1.613 | AH18: -3.23 | AI18: 0.406 | AJ18: 1.822 | AK18: 1.848 | AL18: 3.003 | AM18: 2.139 | AN18: 1.478 | AO18: 0.586 | AP18: 1.289 | AQ18: 0.011 | AR18: 1.608 | AS18: 0.756 | AT18: 0.17 | AU18: 0.429 | AV18: 0.671 | AW18: 1.475 | AX18: 3.204 | AY18: 4.09 | AZ18: 4.119 | BA18: 3.894 | BB18: 3.096 | BC18: 3.021 | BD18: 1.026 | BE18: 1.549 | BF18: 1.382 | BG18: 1.193 | BH18: 0.279 | BI18: 2.378 | BJ18: 2.996 | BK18: 3.994 | BL18: 7.128 | BM18: 6.034 | BN18: 6.575 | BO18: 4.029 | BP18: 1.62 | BQ18: 1.982 | BR18: 1.034 | BS18: 2.082 | BT18: 4.928 | BU18: 5.278 | BV18: 6.896 | BW18: 8.674 | BX18: 10.382 | BY18: 11.3 | BZ18: 11.589
B19: Extremadura | D19: -6.495 | E19: -4.722 | F19: -2.863 | G19: 2.031 | H19: 6.947 | I19: 4.956 | J19: 2.947 | K19: -1.991 | L19: -2.198 | M19: -1 | N19: -0.149 | O19: 1.898 | P19: 2.08 | Q19: 2.967 | R19: -0.881 | S19: 1.653 | T19: -3.745 | U19: -7.847 | V19: -4.701 | W19: -8.001 | X19: -6.998 | Y19: -7.373 | Z19: -9.752 | AA19: -8.628 | AB19: -13.678 | AC19: -15.649 | AD19: -14.043 | AE19: -15.66 | AF19: -7.457 | AG19: -3.495 | AH19: -4.603 | AI19: -0.717 | AJ19: 0.845 | AK19: 0.913 | AL19: 3.333 | AM19: 2.583 | AN19: 1.676 | AO19: 1.288 | AP19: 1.965 | AQ19: 0.79 | AR19: 1.091 | AS19: 0.357 | AT19: 0.026 | AU19: 0.188 | AV19: 0.341 | AW19: 2.195 | AX19: 2.219 | AY19: 2.664 | AZ19: 2.434 | BA19: 1.704 | BB19: 1.497 | BC19: 2.195 | BD19: 0.338 | BE19: 1.285 | BF19: -0.001 | BG19: 0.436 | BH19: -0.186 | BI19: 1.674 | BJ19: 2.862 | BK19: 4.893 | BL19: 6.925 | BM19: 5.336 | BN19: 6.531 | BO19: 2.803 | BP19: 1.074 | BQ19: 1.777 | BR19: 1.057 | BS19: 2.204 | BT19: 5.655 | BU19: 6.17 | BV19: 8.202 | BW19: 9.106 | BX19: 10.921 | BY19: 12.158 | BZ19: 12.536
B20: Catalonia | D20: 1.228 | E20: 5.501 | F20: 9.02 | G20: 11.427 | H20: -1.213 | I20: -5.214 | J20: -8.274 | K20: -10.256 | L20: -13.714 | M20: -13.264 | N20: -11.186 | O20: -7.026 | P20: -3.616 | Q20: -1.983 | R20: -2.28 | S20: -2.752 | T20: -5.46 | U20: -8.205 | V20: -10.337 | W20: -14.309 | X20: -14.941 | Y20: -16.538 | Z20: -17.41 | AA20: -14.318 | AB20: -16.434 | AC20: -13.381 | AD20: -8.09 | AE20: -7.188 | AF20: -0.424 | AG20: 1.577 | AH20: 1.117 | AI20: 2.22 | AJ20: 1.826 | AK20: 5.471 | AL20: 6.085 | AM20: 5.857 | AN20: 8.574 | AO20: 5.51 | AP20: 6.631 | AQ20: 7.444 | AR20: 8.779 | AS20: 9.29 | AT20: 9.95 | AU20: 10.206 | AV20: 8.566 | AW20: 9.331 | AX20: 9.063 | AY20: 8.15 | AZ20: 7.609 | BA20: 5.186 | BB20: 4.67 | BC20: 3.37 | BD20: 3.174 | BE20: 2.323 | BF20: 1.733 | BG20: 0.998 | BH20: 1.217 | BI20: 3.248 | BJ20: 3.284 | BK20: 6.069 | BL20: 7.711 | BM20: 7.214 | BN20: 8.124 | BO20: 5.461 | BP20: 3.486 | BQ20: 3.194 | BR20: 3.781 | BS20: 3.531 | BT20: 5.613 | BU20: 6.677 | BV20: 6.755 | BW20: 10.411 | BX20: 11.651 | BY20: 11.591 | BZ20: 11.289
... B27: Canary Islands | D27: -6.124 | E27: -2.727 | F27: -0.639 | G27: 2.5 | H27: 6.523 | I27: 2.803 | J27: 0.643 | K27: -2.439 | L27: -4.314 | M27: -4.323 | N27: -4.145 | O27: -2.47 | P27: -2.646 | Q27: -1.187 | R27: -2.901 | S27: -3.185 | T27: -3.334 | U27: -5.177 | V27: -6.74 | W27: -7.669 | X27: -10.602 | Y27: -14.311 | Z27: -15.032 | AA27: -13.331 | AB27: -12.171 | AC27: -9.249 | AD27: -5.807 | AE27: -6.805 | AF27: -4.666 | AG27: -0.226 | AH27: -0.617 | AI27: 0.529 | AJ27: 2.003 | AK27: 3.587 | AL27: 4.364 | AM27: 3.624 | AN27: 5.881 | AO27: 1.9 | AP27: 2.362 | AQ27: 3.336 | AR27: 3.441 | AS27: 3.591 | AT27: 4.507 | AU27: 6.035 | AV27: 4.545 | AW27: 5.942 | AX27: 5.366 | AY27: 4.143 | AZ27: 5.188 | BA27: 3.218 | BB27: 3.801 | BC27: 3.052 | BD27: 1.774 | BE27: 0.631 | BF27: 1.434 | BG27: 0.833 | BH27: 1.808 | BI27: 6.394 | BJ27: 6.953 | BK27: 7.809 | BL27: 10.882 | BM27: 9.437 | BN27: 8.052 | BO27: 8.142 | BP27: 5.503 | BQ27: 4.542 | BR27: 6.601 | BS27: 4.545 | BT27: 5.811 | BU27: 8.51 | BV27: 7.108 | BW27: 10.601 | BX27: 12.417 | BY27: 11.65 | BZ27: 12.222
B29: © Terms & conditions | CA29: National and regional house price indices

Sheet Denmark
B1: National and regional house price indices
B2: Reference area type: Large regions
B3: Frequency of observation: Quarterly
B4: Measure: House price index
B5: Combined unit of measure: Percent per annum, Growth rate, over 1 year
B7: Time period | C7: Time period | D7: 1993-Q1 | E7: 1993-Q2 | F7: 1993-Q3 | G7: 1993-Q4 | H7: 1994-Q1 | I7: 1994-Q2 | J7: 1994-Q3 | K7: 1994-Q4 | L7: 1995-Q1 | M7: 1995-Q2 | N7: 1995-Q3 | O7: 1995-Q4 | P7: 1996-Q1 | Q7: 1996-Q2 | R7: 1996-Q3 | S7: 1996-Q4 | T7: 1997-Q1 | U7: 1997-Q2 | V7: 1997-Q3 | W7: 1997-Q4 | X7: 1998-Q1 | Y7: 1998-Q2 | Z7: 1998-Q3 | AA7: 1998-Q4 | AB7: 1999-Q1 | AC7: 1999-Q2 | AD7: 1999-Q3 | AE7: 1999-Q4 | AF7: 2000-Q1 | AG7: 2000-Q2 | AH7: 2000-Q3 | AI7: 2000-Q4 | AJ7: 2001-Q1 | AK7: 2001-Q2 | AL7: 2001-Q3 | AM7: 2001-Q4 | AN7: 2002-Q1 | AO7: 2002-Q2 | AP7: 2002-Q3 | AQ7: 2002-Q4 | AR7: 2003-Q1 | AS7: 2003-Q2 | AT7: 2003-Q3 | AU7: 2003-Q4 | AV7: 2004-Q1 | AW7: 2004-Q2 | AX7: 2004-Q3 | AY7: 2004-Q4 | AZ7: 2005-Q1 | BA7: 2005-Q2 | BB7: 2005-Q3 | BC7: 2005-Q4 | BD7: 2006-Q1 | BE7: 2006-Q2 | BF7: 2006-Q3 | BG7: 2006-Q4 | BH7: 2007-Q1 | BI7: 2007-Q2 | BJ7: 2007-Q3 | BK7: 2007-Q4 | BL7: 2008-Q1 | BM7: 2008-Q2 | BN7: 2008-Q3 | BO7: 2008-Q4 | BP7: 2009-Q1 | BQ7: 2009-Q2 | BR7: 2009-Q3 | BS7: 2009-Q4 | BT7: 2010-Q1 | BU7: 2010-Q2 | BV7: 2010-Q3 | BW7: 2010-Q4 | BX7: 2011-Q1 | BY7: 2011-Q2 | BZ7: 2011-Q3 | CA7: 2011-Q4 | CB7: 2012-Q1 | CC7: 2012-Q2 | CD7: 2012-Q3 | CE7: 2012-Q4 | CF7: 2013-Q1 | CG7: 2013-Q2 | CH7: 2013-Q3 | CI7: 2013-Q4 | CJ7: 2014-Q1 | CK7: 2014-Q2 | CL7: 2014-Q3 | CM7: 2014-Q4 | CN7: 2015-Q1 | CO7: 2015-Q2 | CP7: 2015-Q3 | CQ7: 2015-Q4 | CR7: 2016-Q1 | CS7: 2016-Q2 | CT7: 2016-Q3 | CU7: 2016-Q4 | CV7: 2017-Q1 | CW7: 2017-Q2 | CX7: 2017-Q3 | CY7: 2017-Q4 | CZ7: 2018-Q1 | DA7: 2018-Q2 | DB7: 2018-Q3 | DC7: 2018-Q4 | DD7: 2019-Q1 | DE7: 2019-Q2 | DF7: 2019-Q3 | DG7: 2019-Q4 | DH7: 2020-Q1 | DI7: 2020-Q2 | DJ7: 2020-Q3 | DK7: 2020-Q4 | DL7: 2021-Q1 | DM7: 2021-Q2 | DN7: 2021-Q3 | DO7: 2021-Q4 | DP7: 2022-Q1 | DQ7: 2022-Q2 | DR7: 2022-Q3 | DS7: 2022-Q4 | DT7: 2023-Q1 | DU7: 2023-Q2 | DV7: 2023-Q3 | DW7: 2023-Q4 | DX7: 2024-Q1 | DY7: 2024-Q2 | DZ7: 2024-Q3 | EA7: 2024-Q4 | EB7: 2025-Q1 | EC7: 2025-Q2 | ED7: 2025-Q3
B8: Dwellings
B9: Reference area: Capital region
B10: Single family | D10: -6.748 | E10: -6.748 | F10: 0 | G10: 9.74 | H10: 17.763 | I10: 17.763 | J10: 12.579 | K10: 7.692 | L10: 4.469 | M10: 8.939 | N10: 12.291 | O10: 13.736 | P10: 12.834 | Q10: 11.795 | R10: 11.443 | S10: 13.043 | T10: 13.744 | U10: 13.761 | V10: 15.179 | W10: 11.538 | X10: 10.417 | Y10: 12.097 | Z10: 9.302 | AA10: 11.494 | AB10: 11.698 | AC10: 8.633 | AD10: 9.929 | AE10: 6.186 | AF10: 7.432 | AG10: 9.934 | AH10: 9.355 | AI10: 12.945 | AJ10: 12.893 | AK10: 9.337 | AL10: 9.735 | AM10: 6.304 | AN10: 5.292 | AO10: 6.887 | AP10: 4.839 | AQ10: 6.199 | AR10: 3.704 | AS10: 3.351 | AT10: 3.59 | AU10: 2.792 | AV10: 6.888 | AW10: 9.476 | AX10: 12.624 | AY10: 15.309 | AZ10: 17.9 | BA10: 21.64 | BB10: 27.473 | BC10: 34.69 | BD10: 36.842 | BE10: 37.453 | BF10: 28.793 | BG10: 17.329 | BH10: 6.805 | BI10: -2.725 | BJ10: -4.819 | BK10: -7.453 | BL10: -7.895 | BM10: -6.723 | BN10: -11.252 | BO10: -17.277 | BP10: -21.203 | BQ10: -20.721 | BR10: -14.739 | BS10: -3.186 | BT10: 5.725 | BU10: 9.47 | BV10: 7.435 | BW10: 7.313 | BX10: 3.249 | BY10: 0.346 | BZ10: -2.941 | CA10: -8.518 | CB10: -6.119 | CC10: -6.552 | CD10: -3.03 | CE10: 2.98 | CF10: 4.097 | CG10: 5.535 | CH10: 5.882 | CI10: 5.244 | CJ10: 4.472 | CK10: 5.245 | CL10: 5.903 | CM10: 4.467 | CN10: 6.849 | CO10: 8.97 | CP10: 8.361 | CQ10: 9.539 | CR10: 9.135 | CS10: 4.878 | CT10: 5.144 | CU10: 4.054 | CV10: 3.965 | CW10: 5.523 | CX10: 5.755 | CY10: 6.205 | CZ10: 5.932 | DA10: 5.923 | DB10: 4.354 | DC10: 4.348 | DD10: 3.333 | DE10: 2.731 | DF10: 3.52 | DG10: 3.516 | DH10: 2.968 | DI10: 2.278 | DJ10: 7.053 | DK10: 10.818 | DL10: 16.541 | DM10: 19.678 | DN10: 18.353 | DO10: 12.826 | DP10: 9.785 | DQ10: 6.515 | DR10: 0 | DS10: -5.131 | DT10: -8.717 | DU10: -7.767 | DV10: -2.982 | DW10: 3.818 | DX10: 3.755 | DY10: 6.105 | DZ10: 3.996 | EA10: 5.516 | EB10: 9.411 | EC10: 7.341 | ED10: 9.655
B11: Multi family | D11: -11.811 | E11: -10.484 | F11: -1.681 | G11: 6.14 | H11: 15.179 | I11: 13.514 | J11: 6.838 | K11: 3.306 | L11: -1.55 | M11: 5.556 | N11: 8.8 | O11: 12 | P11: 13.386 | Q11: 11.278 | R11: 11.765 | S11: 12.143 | T11: 12.5 | U11: 13.514 | V11: 13.816 | W11: 12.102 | X11: 14.198 | Y11: 16.071 | Z11: 16.763 | AA11: 19.318 | AB11: 17.297 | AC11: 16.923 | AD11: 17.327 | AE11: 14.286 | AF11: 16.59 | AG11: 14.912 | AH11: 14.346 | AI11: 17.083 | AJ11: 16.601 | AK11: 17.176 | AL11: 17.343 | AM11: 14.235 | AN11: 13.559 | AO11: 13.029 | AP11: 11.635 | AQ11: 10.28 | AR11: 11.045 | AS11: 7.781 | AT11: 6.761 | AU11: 5.085 | AV11: 3.226 | AW11: 6.684 | AX11: 8.443 | AY11: 15.323 | AZ11: 19.271 | BA11: 25.063 | BB11: 31.873 | BC11: 35.198 | BD11: 36.245 | BE11: 35.671 | BF11: 25.83 | BG11: 12.931 | BH11: 0.641 | BI11: -8.863 | BJ11: -11.144 | BK11: -11.756 | BL11: -9.076 | BM11: -10.373 | BN11: -13.036 | BO11: -13.495 | BP11: -21.891 | BQ11: -17.722 | BR11: -13.093 | BS11: -6.6 | BT11: 7.175 | BU11: 7.912 | BV11: 7.86 | BW11: 6.852 | BX11: 5.23 | BY11: 3.462 | BZ11: -2.429 | CA11: -4.208 | CB11: -4.374 | CC11: -4.331 | CD11: 4.149 | CE11: 5.439 | CF11: 8.108 | CG11: 11.317 | CH11: 7.968 | CI11: 9.921 | CJ11: 10.962 | CK11: 9.057 | CL11: 9.963 | CM11: 8.123 | CN11: 8.319 | CO11: 11.356 | CP11: 12.416 | CQ11: 13.022 | CR11: 11.84 | CS11: 8.371 | CT11: 7.761 | CU11: 8.124 | CV11: 7.153 | CW11: 8.427 | CX11: 9.141 | CY11: 8.197 | CZ11: 8.678 | DA11: 7.772 | DB11: 4.822 | DC11: 2.525 | DD11: 0.737 | DE11: -0.361 | DF11: -0.484 | DG11: 2.586 | DH11: 3.415 | DI11: 3.136 | DJ11: 7.056 | DK11: 8.283 | DL11: 12.618 | DM11: 14.386 | DN11: 13.523 | DO11: 10.2 | DP11: 6.702 | DQ11: 5.726 | DR11: -0.1 | DS11: -4.527 | DT11: -7.655 | DU11: -6.093 | DV11: -1.303 | DW11: 3.899 | DX11: 4.145 | DY11: 4.325 | DZ11: 5.482 | EA11: 7.404 | EB11: 11.633 | EC11: 12.537 | ED11: 11.935
D12: =AVERAGE(D10:D11) -> -9.2795 | E12: =AVERAGE(E10:E11) -> -8.616 | F12: =AVERAGE(F10:F11) -> -0.8405 | G12: =AVERAGE(G10:G11) -> 7.94 | H12: =AVERAGE(H10:H11) -> 16.471 | I12: =AVERAGE(I10:I11) -> 15.6385 | J12: =AVERAGE(J10:J11) -> 9.7085 | K12: =AVERAGE(K10:K11) -> 5.499 | ... ED12: =AVERAGE(ED10:ED11) -> 10.795
B13: Reference area: Zealand
B14: Single family | D14: -6.415 | E14: -6.792 | F14: -0.772 | G14: 9.163 | H14: 15.323 | I14: 15.789 | J14: 9.339 | K14: 4.015 | L14: 1.399 | M14: 5.594 | N14: 10.676 | O14: 11.93 | P14: 10.69 | Q14: 7.285 | R14: 8.039 | S14: 10.031 | T14: 12.773 | U14: 14.506 | V14: 12.798 | W14: 9.402 | X14: 7.459 | Y14: 9.434 | Z14: 7.916 | AA14: 8.854 | AB14: 9.512 | AC14: 6.404 | AD14: 8.313 | AE14: 6.699 | AF14: 7.277 | AG14: 8.333 | AH14: 9.932 | AI14: 9.193 | AJ14: 9.847 | AK14: 10.47 | AL14: 7.187 | AM14: 6.982 | AN14: 4.582 | AO14: 3.675 | AP14: 4.406 | AQ14: 5.182 | AR14: 5.143 | AS14: 5.41 | AT14: 5.505 | AU14: 4.38 | AV14: 6.341 | AW14: 6.726 | AX14: 8.174 | AY14: 11.364 | AZ14: 12.436 | BA14: 13.765 | BB14: 19.293 | BC14: 21.036 | BD14: 24.091 | BE14: 28.134 | BF14: 22.507 | BG14: 18.029 | BH14: 12.698 | BI14: 5.461 | BJ14: 1.54 | BK14: -0.549 | BL14: -3.792 | BM14: -4.315 | BN14: -6.826 | BO14: -14.254 | BP14: -18.243 | BQ14: -18.264 | BR14: -16.047 | BS14: -7.99 | BT14: -1.102 | BU14: -0.276 | BV14: 0 | BW14: -1.541 | BX14: -3.621 | BY14: -4.426 | BZ14: -6.233 | CA14: -8.535 | CB14: -7.659 | CC14: -6.946 | CD14: -6.204 | CE14: -1.866 | CF14: -0.156 | CG14: 0.467 | CH14: 2.205 | CI14: 2.06 | CJ14: 1.567 | CK14: 1.703 | CL14: 0.154 | CM14: 2.019 | CN14: 3.858 | CO14: 7.002 | CP14: 8.615 | CQ14: 6.545 | CR14: 4.903 | CS14: 3.414 | CT14: 5.666 | CU14: 4.857 | CV14: 5.099 | CW14: 6.74 | CX14: 4.692 | CY14: 5.586 | CZ14: 8.356 | DA14: 4.51 | DB14: 3.841 | DC14: 5.29 | DD14: 2.363 | DE14: 2.959 | DF14: 3.946 | DG14: 2.574 | DH14: 2.673 | DI14: 2.275 | DJ14: 3.084 | DK14: 6.93 | DL14: 11.361 | DM14: 15.222 | DN14: 15.075 | DO14: 11.508 | DP14: 9.139 | DQ14: 3.862 | DR14: 0.3 | DS14: -4.91 | DT14: -8.179 | DU14: -7.045 | DV14: -3.091 | DW14: 1.897 | DX14: 5.408 | DY14: 5.368 | DZ14: 4.012 | EA14: 6.618 | EB14: 4.225 | EC14: 6.593 | ED14: 6.924
B15: Multi family | D15: -6.038 | E15: -8.494 | F15: -6.13 | G15: 7.083 | H15: 9.237 | I15: 13.08 | J15: 6.939 | K15: -0.389 | L15: -4.779 | M15: 4.104 | N15: 6.107 | O15: 11.328 | P15: 9.653 | Q15: 6.452 | R15: 8.273 | S15: 8.772 | T15: 10.211 | U15: 9.764 | V15: 10.299 | W15: 7.419 | X15: 5.751 | Y15: 4.601 | Z15: 6.928 | AA15: 8.709 | AB15: 12.689 | AC15: 10.557 | AD15: 12.394 | AE15: 9.669 | AF15: 10.992 | AG15: 12.202 | AH15: 10.777 | AI15: 12.594 | AJ15: 12.077 | AK15: 12.53 | AL15: 10.407 | AM15: 10.291 | AN15: 9.267 | AO15: 9.454 | AP15: 8.197 | AQ15: 10.548 | AR15: 12.229 | AS15: 8.829 | AT15: 10.417 | AU15: 3.853 | AV15: 1.757 | AW15: 6.349 | AX15: 5.832 | AY15: 10.954 | AZ15: 12.435 | BA15: 14.096 | BB15: 14.749 | BC15: 17.357 | BD15: 24.117 | BE15: 28.488 | BF15: 25.424 | BG15: 24.016 | BH15: 11.634 | BI15: 3.507 | BJ15: 0.225 | BK15: -6.783 | BL15: -7.539 | BM15: -5.574 | BN15: -8.764 | BO15: -9.977 | BP15: -12.83 | BQ15: -15.046 | BR15: -15.271 | BS15: -8.866 | BT15: -2.613 | BU15: -5.041 | BV15: 2.326 | BW15: 1.431 | BX15: -1.977 | BY15: -4.735 | BZ15: -5.54 | CA15: -11.989 | CB15: -12.104 | CC15: -2.56 | CD15: -5.263 | CE15: 0.321 | CF15: 3.934 | CG15: -2.782 | CH15: 3.492 | CI15: 4.153 | CJ15: 1.893 | CK15: 4.293 | CL15: 1.687 | CM15: 3.374 | CN15: 7.121 | CO15: 6.098 | CP15: 10.256 | CQ15: 3.561 | CR15: 7.948 | CS15: 9.626 | CT15: 3.694 | CU15: 12.464 | CV15: 4.15 | CW15: 4.718 | CX15: 8.047 | CY15: 5.096 | CZ15: 3.728 | DA15: 5.507 | DB15: 5.983 | DC15: 0.97 | DD15: 7.683 | DE15: 3.796 | DF15: 2.88 | DG15: 4.082 | DH15: 2.647 | DI15: 2.171 | DJ15: 1.008 | DK15: 6.228 | DL15: 7.623 | DM15: 13.087 | DN15: 11.641 | DO15: 6.406 | DP15: 6.563 | DQ15: 4.946 | DR15: -2.681 | DS15: -4.49 | DT15: -7.136 | DU15: -6.692 | DV15: 0.714 | DW15: 7.158 | DX15: 9.684 | DY15: 2.525 | DZ15: 5.268 | EA15: 5.683 | EB15: 0.864 | EC15: 6.7 | ED15: 6.833
D16: =AVERAGE(D14:D15) -> -6.2265 | E16: =AVERAGE(E14:E15) -> -7.643 | F16: =AVERAGE(F14:F15) -> -3.451 | G16: =AVERAGE(G14:G15) -> 8.123 | H16: =AVERAGE(H14:H15) -> 12.28 | I16: =AVERAGE(I14:I15) -> 14.4345 | J16: =AVERAGE(J14:J15) -> 8.139 | K16: =AVERAGE(K14:K15) -> 1.813 | ... ED16: =AVERAGE(ED14:ED15) -> 6.8785
B17: Reference area: Southern Denmark
B18: Single family | D18: -3.846 | E18: -4.167 | F18: 0.647 | G18: 9.272 | H18: 16 | I18: 16.054 | J18: 10.289 | K18: 4.545 | L18: 1.437 | M18: 5.187 | N18: 9.329 | O18: 11.014 | P18: 11.048 | Q18: 10.411 | R18: 9.867 | S18: 11.749 | T18: 11.735 | U18: 11.166 | V18: 11.165 | W18: 7.71 | X18: 7.991 | Y18: 8.482 | Z18: 8.734 | AA18: 8.894 | AB18: 6.977 | AC18: 5.35 | AD18: 3.614 | AE18: 3.785 | AF18: 2.964 | AG18: 4.102 | AH18: 4.07 | AI18: 3.263 | AJ18: 4.223 | AK18: 2.439 | AL18: 2.421 | AM18: 0.929 | AN18: -0.184 | AO18: 0.733 | AP18: 0.182 | AQ18: 0.737 | AR18: 1.292 | AS18: 0.909 | AT18: 1.815 | AU18: 2.742 | AV18: 4.189 | AW18: 6.486 | AX18: 6.952 | AY18: 9.075 | AZ18: 9.441 | BA18: 11.675 | BB18: 13.167 | BC18: 14.519 | BD18: 19.649 | BE18: 18.03 | BF18: 18.999 | BG18: 16.239 | BH18: 13.218 | BI18: 12.452 | BJ18: 8.911 | BK18: 7.966 | BL18: 4.599 | BM18: 3.539 | BN18: 1.818 | BO18: -2.724 | BP18: -7.554 | BQ18: -10.695 | BR18: -9.263 | BS18: -6.768 | BT18: -3.293 | BU18: -0.617 | BV18: -0.369 | BW18: -0.25 | BX18: -1.513 | BY18: -1.988 | BZ18: -5.062 | CA18: -6.775 | CB18: -4.738 | CC18: -6.464 | CD18: -3.511 | CE18: -1.48 | CF18: -1.882 | CG18: 0.813 | CH18: 0 | CI18: -0.546 | CJ18: 0.274 | CK18: 2.823 | CL18: 0.943 | CM18: 2.885 | CN18: 5.328 | CO18: 3.268 | CP18: 5.073 | CQ18: 3.872 | CR18: 2.335 | CS18: 1.266 | CT18: 2.922 | CU18: 2.828 | CV18: 1.521 | CW18: 3.5 | CX18: 1.975 | CY18: 1.75 | CZ18: 5.993 | DA18: 3.382 | DB18: 4.116 | DC18: 5.405 | DD18: 2.473 | DE18: 2.921 | DF18: 3.372 | DG18: 3.613 | DH18: 1.264 | DI18: 1.589 | DJ18: 3.15 | DK18: 5.287 | DL18: 8.627 | DM18: 11.397 | DN18: 8.506 | DO18: 6.944 | DP18: 6.374 | DQ18: 2.808 | DR18: 0.402 | DS18: -4.396 | DT18: -5.501 | DU18: -2.732 | DV18: -0.1 | DW18: 3.657 | DX18: 4.262 | DY18: 2.006 | DZ18: 0.501 | EA18: 2.419 | EB18: 3.789 | EC18: 2.458 | ED18: 5.783
B19: Multi family | D19: -6.643 | E19: -9.622 | F19: -1.46 | G19: 4.693 | H19: 11.985 | I19: 12.167 | J19: 6.667 | K19: 1.724 | L19: -1.003 | M19: 5.085 | N19: 9.722 | O19: 8.475 | P19: 9.459 | Q19: 7.742 | R19: 6.013 | S19: 9.375 | T19: 12.346 | U19: 11.377 | V19: 13.433 | W19: 11.143 | X19: 7.143 | Y19: 9.946 | Z19: 6.842 | AA19: 5.913 | AB19: 10 | AC19: 6.357 | AD19: 8.621 | AE19: 5.34 | AF19: 7.692 | AG19: 7.816 | AH19: 7.029 | AI19: 8.525 | AJ19: 3.463 | AK19: 5.33 | AL19: 3.814 | AM19: 6.157 | AN19: 5.439 | AO19: 2.632 | AP19: 4.898 | AQ19: 3 | AR19: 5.159 | AS19: 12.032 | AT19: 6.226 | AU19: 4.854 | AV19: 3.208 | AW19: 0 | AX19: 6.044 | AY19: 10.556 | AZ19: 13.711 | BA19: 12.852 | BB19: 17.098 | BC19: 18.258 | BD19: 21.383 | BE19: 23.869 | BF19: 19.174 | BG19: 13.173 | BH19: 11.523 | BI19: 7.305 | BJ19: 3.342 | BK19: 5.257 | BL19: -1.663 | BM19: -2.465 | BN19: 0.599 | BO19: -7.253 | BP19: -7.85 | BQ19: -10.71 | BR19: -8.571 | BS19: -6.154 | BT19: -4.98 | BU19: 2.156 | BV19: 1.302 | BW19: 5.874 | BX19: 0.828 | BY19: -7.256 | BZ19: -9.126 | CA19: -11.484 | CB19: -6.566 | CC19: -9.104 | CD19: 3.96 | CE19: 2.332 | CF19: 4.1 | CG19: 13.302 | CH19: 0.272 | CI19: 3.989 | CJ19: 0.985 | CK19: 2.21 | CL19: 1.493 | CM19: -0.685 | CN19: 7.66 | CO19: 5 | CP19: 7.219 | CQ19: 13.103 | CR19: 2.587 | CS19: 5.019 | CT19: 4.364 | CU19: 0.366 | CV19: 4.792 | CW19: 4.657 | CX19: 2.031 | CY19: 4.01 | CZ19: 9.747 | DA19: 6.792 | DB19: 7.26 | DC19: 10.864 | DD19: 3.18 | DE19: 7.785 | DF19: 3.493 | DG19: -1.897 | DH19: -1.594 | DI19: -4.171 | DJ19: -0.422 | DK19: 0.859 | DL19: 6.156 | DM19: 4.14 | DN19: 8.369 | DO19: 5.964 | DP19: 2.747 | DQ19: 4.179 | DR19: -2.542 | DS19: -2.412 | DT19: -4.059 | DU19: -1.174 | DV19: 1.304 | DW19: 5.252 | DX19: 1.548 | DY19: -0.099 | DZ19: -2.772 | EA19: 1.468 | EB19: 9.756 | EC19: 3.271 | ED19: 6.823
D20: =AVERAGE(D18:D19) -> -5.2445 | E20: =AVERAGE(E18:E19) -> -6.8945 | F20: =AVERAGE(F18:F19) -> -0.4065 | G20: =AVERAGE(G18:G19) -> 6.9825 | H20: =AVERAGE(H18:H19) -> 13.9925 | I20: =AVERAGE(I18:I19) -> 14.1105 | J20: =AVERAGE(J18:J19) -> 8.478 | K20: =AVERAGE(K18:K19) -> 3.1345 | ... ED20: =AVERAGE(ED18:ED19) -> 6.303
B21: Reference area: Central Denmark
B22: Single family | D22: -5.614 | E22: -6.316 | F22: 0 | G22: 7.299 | H22: 16.357 | I22: 17.228 | J22: 9.22 | K22: 5.782 | L22: 2.236 | M22: 5.431 | N22: 9.091 | O22: 11.897 | P22: 10.313 | Q22: 9.394 | R22: 11.012 | S22: 11.494 | T22: 12.465 | U22: 13.019 | V22: 10.724 | W22: 7.99 | X22: 7.053 | Y22: 7.598 | Z22: 7.506 | AA22: 6.444 | AB22: 6.118 | AC22: 3.872 | AD22: 5.405 | AE22: 4.484 | AF22: 4.213 | AG22: 4.605 | AH22: 3.419 | AI22: 4.506 | AJ22: 4.681 | AK22: 3.774 | AL22: 2.066 | AM22: 1.232 | AN22: 1.016 | AO22: 1.212 | AP22: 1.417 | AQ22: 1.217 | AR22: 0.604 | AS22: 2.595 | AT22: 3.393 | AU22: 3.808 | AV22: 7 | AW22: 8.366 | AX22: 9.653 | AY22: 11.969 | AZ22: 12.71 | BA22: 13.465 | BB22: 16.725 | BC22: 19.31 | BD22: 22.388 | BE22: 22.943 | BF22: 19.608 | BG22: 14.306 | BH22: 10.705 | BI22: 7.336 | BJ22: 6.557 | BK22: 4.804 | BL22: 1.102 | BM22: 1.799 | BN22: -2.13 | BO22: -5.911 | BP22: -9.806 | BQ22: -11.779 | BR22: -8.948 | BS22: -5.256 | BT22: 0.268 | BU22: 2.136 | BV22: 1.992 | BW22: 3.112 | BX22: 1.071 | BY22: -1.307 | BZ22: -3.906 | CA22: -4.331 | CB22: -5.828 | CC22: -4.371 | CD22: -1.626 | CE22: -2.332 | CF22: 2.391 | CG22: 1.801 | CH22: 0.275 | CI22: 1.966 | CJ22: 1.374 | CK22: 2.041 | CL22: 1.511 | CM22: 2.755 | CN22: 4.201 | CO22: 3.733 | CP22: 4.465 | CQ22: 4.29 | CR22: 1.821 | CS22: 1.671 | CT22: 2.979 | CU22: 2.314 | CV22: 2.171 | CW22: 3.413 | CX22: 3.27 | CY22: 3.266 | CZ22: 3.125 | DA22: 3.912 | DB22: 3.289 | DC22: 1.825 | DD22: 2.667 | DE22: 2.118 | DF22: 2.358 | DG22: 3.943 | DH22: 2.715 | DI22: 2.65 | DJ22: 5.184 | DK22: 6.322 | DL22: 9.885 | DM22: 10.213 | DN22: 8.324 | DO22: 8.541 | DP22: 5.753 | DQ22: 4.073 | DR22: 1.314 | DS22: -3.884 | DT22: -3.956 | DU22: -3.033 | DV22: -0.1 | DW22: 3.938 | DX22: 1.751 | DY22: 2.926 | DZ22: 0.799 | EA22: 2.493 | EB22: 3.947 | EC22: 3.039 | ED22: 4.46
B23: Multi family | D23: -10.744 | E23: -7.595 | F23: -2.137 | G23: 4.803 | H23: 16.204 | I23: 15.068 | J23: 8.297 | K23: 0.833 | L23: -0.797 | M23: 3.571 | N23: 9.274 | O23: 12.81 | P23: 10.843 | Q23: 9.195 | R23: 10.332 | S23: 12.821 | T23: 15.58 | U23: 14.035 | V23: 11.371 | W23: 11.688 | X23: 5.643 | Y23: 8 | Z23: 6.006 | AA23: 4.07 | AB23: 9.496 | AC23: 6.268 | AD23: 8.782 | AE23: 8.939 | AF23: 5.962 | AG23: 6.971 | AH23: 5.469 | AI23: 3.333 | AJ23: 5.882 | AK23: 4.261 | AL23: 5.679 | AM23: 4.715 | AN23: 4.348 | AO23: 6.25 | AP23: 4.439 | AQ23: 4.976 | AR23: 6.25 | AS23: 7.014 | AT23: 7.606 | AU23: 8.804 | AV23: 9.15 | AW23: 13.319 | AX23: 16.008 | AY23: 18.05 | AZ23: 18.762 | BA23: 17.351 | BB23: 18.996 | BC23: 20.914 | BD23: 23.866 | BE23: 24.483 | BF23: 19.88 | BG23: 15.988 | BH23: 5.292 | BI23: -0.639 | BJ23: -5.151 | BK23: -9.398 | BL23: -5.541 | BM23: -4.242 | BN23: -4.636 | BO23: -7.192 | BP23: -12.278 | BQ23: -9.799 | BR23: -6.25 | BS23: -0.745 | BT23: 6.532 | BU23: 6.101 | BV23: 5.63 | BW23: 4.505 | BX23: 4.234 | BY23: 0.561 | BZ23: -2.805 | CA23: -3.161 | CB23: -3.221 | CC23: -2.51 | CD23: 0.289 | CE23: 3.858 | CF23: -0.289 | CG23: 2.003 | CH23: 5.324 | CI23: 1.429 | CJ23: 1.742 | CK23: 4.348 | CL23: 2.459 | CM23: 6.62 | CN23: 8.845 | CO23: 7.124 | CP23: 8 | CQ23: 4.095 | CR23: 8.519 | CS23: 5.019 | CT23: 4.198 | CU23: 3.807 | CV23: 2.536 | CW23: 2.27 | CX23: 2.844 | CY23: 7.335 | CZ23: 3.298 | DA23: 5.257 | DB23: 2.995 | DC23: -0.456 | DD23: 1.482 | DE23: 0 | DF23: 1.119 | DG23: 0.801 | DH23: -1.461 | DI23: 1.221 | DJ23: 3.65 | DK23: 7.719 | DL23: 11.631 | DM23: 10.746 | DN23: 8.324 | DO23: 6.955 | DP23: 5.72 | DQ23: 2.178 | DR23: -3.054 | DS23: -6.502 | DT23: -6.86 | DU23: -4.845 | DV23: 1.728 | DW23: 3.267 | DX23: 2.075 | DY23: -0.407 | DZ23: -1.798 | EA23: 1.122 | EB23: 2.337 | EC23: 5.828 | ED23: 7.731
D24: =AVERAGE(D22:D23) -> -8.179 | E24: =AVERAGE(E22:E23) -> -6.9555 | F24: =AVERAGE(F22:F23) -> -1.0685 | G24: =AVERAGE(G22:G23) -> 6.051 | H24: =AVERAGE(H22:H23) -> 16.2805 | I24: =AVERAGE(I22:I23) -> 16.148 | J24: =AVERAGE(J22:J23) -> 8.7585 | K24: =AVERAGE(K22:K23) -> 3.3075 | ... ED24: =AVERAGE(ED22:ED23) -> 6.0955
B25: Reference area: Northern Denmark
B26: Single family | D26: -5.9 | E26: -7.918 | F26: 0.303 | G26: 7.034 | H26: 15.674 | I26: 18.153 | J26: 9.366 | K26: 4.857 | L26: 1.355 | M26: 3.774 | N26: 8.287 | O26: 10.354 | P26: 7.487 | Q26: 7.013 | R26: 7.143 | S26: 7.654 | T26: 11.94 | U26: 12.136 | V26: 10.952 | W26: 8.028 | X26: 5.778 | Y26: 7.792 | Z26: 8.584 | AA26: 7.006 | AB26: 8.403 | AC26: 4.819 | AD26: 4.15 | AE26: 4.762 | AF26: 3.682 | AG26: 4.215 | AH26: 6.452 | AI26: 4.924 | AJ26: 5.421 | AK26: 4.596 | AL26: 1.783 | AM26: 0.542 | AN26: -0.532 | AO26: 1.582 | AP26: -0.175 | AQ26: 2.334 | AR26: 2.317 | AS26: -0.173 | AT26: 1.93 | AU26: 2.456 | AV26: 3.136 | AW26: 6.412 | AX26: 8.262 | AY26: 6.678 | AZ26: 8.784 | BA26: 10.423 | BB26: 8.426 | BC26: 14.125 | BD26: 16.615 | BE26: 15.782 | BF26: 17.155 | BG26: 11.814 | BH26: 9.188 | BI26: 7.898 | BJ26: 7.384 | BK26: 8.428 | BL26: 6.22 | BM26: 1.653 | BN26: -0.117 | BO26: -5.22 | BP26: -10.103 | BQ26: -7.201 | BR26: -6.068 | BS26: -3.06 | BT26: 0 | BU26: -1.627 | BV26: 0.373 | BW26: -0.631 | BX26: -0.511 | BY26: 2.672 | BZ26: -2.847 | CA26: -5.083 | CB26: -3.466 | CC26: -4.833 | CD26: -2.93 | CE26: 2.945 | CF26: 1.995 | CG26: 1.563 | CH26: -1.312 | CI26: -0.78 | CJ26: 0.913 | CK26: 2.179 | CL26: 5.452 | CM26: 3.539 | CN26: 5.943 | CO26: 4.015 | CP26: 3.909 | CQ26: 3.418 | CR26: 1.951 | CS26: 2.654 | CT26: 4.854 | CU26: 3.672 | CV26: 4.665 | CW26: 3.525 | CX26: 2.315 | CY26: 3.896 | CZ26: 1.829 | DA26: 2.157 | DB26: 1.471 | DC26: 0.114 | DD26: 0.449 | DE26: 1.778 | DF26: 3.456 | DG26: 2.043 | DH26: 0.894 | DI26: -0.655 | DJ26: 0.754 | DK26: 5.784 | DL26: 8.306 | DM26: 8.681 | DN26: 6.845 | DO26: 4.522 | DP26: 4.192 | DQ26: 2.831 | DR26: -1.301 | DS26: -1.61 | DT26: -5.299 | DU26: -4.13 | DV26: 0.203 | DW26: -0.818 | DX26: 3.627 | DY26: 4.923 | DZ26: 1.417 | EA26: 2.99 | EB26: 0.9 | EC26: -1.369 | ED26: 0.998
B27: Multi family | D27: -9.921 | E27: -6.939 | F27: 0.424 | G27: 5.957 | H27: 14.097 | I27: 14.035 | J27: 8.017 | K27: 3.213 | L27: 0 | M27: 2.692 | N27: 6.25 | O27: 8.949 | P27: 13.127 | Q27: 11.61 | R27: 13.971 | S27: 13.214 | T27: 11.263 | U27: 12.416 | V27: 11.613 | W27: 11.356 | X27: 10.736 | Y27: 11.94 | Z27: 13.006 | AA27: 13.314 | AB27: 15.235 | AC27: 13.867 | AD27: 12.276 | AE27: 8 | AF27: 5.769 | AG27: 7.026 | AH27: 2.278 | AI27: 5.556 | AJ27: 4.545 | AK27: 0.656 | AL27: 6.013 | AM27: 2.851 | AN27: 2.826 | AO27: 1.304 | AP27: -0.84 | AQ27: -1.493 | AR27: -0.634 | AS27: 2.575 | AT27: 5.085 | AU27: 3.896 | AV27: 6.383 | AW27: 4.603 | AX27: 3.629 | AY27: 11.458 | AZ27: 5.8 | BA27: 12 | BB27: 14.008 | BC27: 13.271 | BD27: 20.416 | BE27: 22.857 | BF27: 25.427 | BG27: 16.832 | BH27: 13.972 | BI27: 3.779 | BJ27: -1.769 | BK27: 1.836 | BL27: 0 | BM27: 0 | BN27: -2.355 | BO27: -6.103 | BP27: -6.749 | BQ27: -5.042 | BR27: -4.823 | BS27: -1.034 | BT27: 1.329 | BU27: 6.637 | BV27: 5.365 | BW27: 3.433 | BX27: 1.895 | BY27: -0.968 | BZ27: -4.668 | CA27: -0.866 | CB27: -1.86 | CC27: -3.212 | CD27: 0.742 | CE27: 3.057 | CF27: 7.289 | CG27: 4.473 | CH27: 10.751 | CI27: 4.237 | CJ27: -1.359 | CK27: 5.663 | CL27: 3.59 | CM27: 5.556 | CN27: 9.642 | CO27: 9.804 | CP27: 7.189 | CQ27: 6.033 | CR27: 9.171 | CS27: 6.905 | CT27: 7.784 | CU27: 11.985 | CV27: 6.674 | CW27: 6.013 | CX27: 8.778 | CY27: 2.378 | CZ27: 3.883 | DA27: 2.101 | DB27: -2.451 | DC27: -0.95 | DD27: -6.957 | DE27: -0.823 | DF27: -0.733 | DG27: -4.904 | DH27: 5.804 | DI27: -0.519 | DJ27: -0.316 | DK27: 9.865 | DL27: 2.426 | DM27: 2.711 | DN27: 7.831 | DO27: 1.633 | DP27: 4.84 | DQ27: 4.467 | DR27: -5.201 | DS27: -0.904 | DT27: -6.778 | DU27: -10.593 | DV27: 1.553 | DW27: -4.053 | DX27: 1.054 | DY27: 4.13 | DZ27: 2.039 | EA27: 0.739 | EB27: -0.521 | EC27: 0.731 | ED27: -2.198
D28: =AVERAGE(D26:D27) -> -7.9105 | E28: =AVERAGE(E26:E27) -> -7.4285 | F28: =AVERAGE(F26:F27) -> 0.3635 | G28: =AVERAGE(G26:G27) -> 6.4955 | H28: =AVERAGE(H26:H27) -> 14.8855 | I28: =AVERAGE(I26:I27) -> 16.094 | J28: =AVERAGE(J26:J27) -> 8.6915 | K28: =AVERAGE(K26:K27) -> 4.035 | ... ED28: =AVERAGE(ED26:ED27) -> -0.6
B29: © Terms & conditions | EE29: National and regional house price indices

Sheet Poland
B1: National and regional house price indices
B2: Reference area type: Large regions
B3: Frequency of observation: Quarterly
B4: Measure: House price index
B5: Combined unit of measure: Percent per annum, Growth rate, over 1 year
B7: Time period | C7: Time period | D7: 2011-Q1 | E7: 2011-Q2 | F7: 2011-Q3 | G7: 2011-Q4 | H7: 2012-Q1 | I7: 2012-Q2 | J7: 2012-Q3 | K7: 2012-Q4 | L7: 2013-Q1 | M7: 2013-Q2 | N7: 2013-Q3 | O7: 2013-Q4 | P7: 2014-Q1 | Q7: 2014-Q2 | R7: 2014-Q3 | S7: 2014-Q4 | T7: 2015-Q1 | U7: 2015-Q2 | V7: 2015-Q3 | W7: 2015-Q4 | X7: 2016-Q1 | Y7: 2016-Q2 | Z7: 2016-Q3 | AA7: 2016-Q4 | AB7: 2017-Q1 | AC7: 2017-Q2 | AD7: 2017-Q3 | AE7: 2017-Q4 | AF7: 2018-Q1 | AG7: 2018-Q2 | AH7: 2018-Q3 | AI7: 2018-Q4 | AJ7: 2019-Q1 | AK7: 2019-Q2 | AL7: 2019-Q3 | AM7: 2019-Q4 | AN7: 2020-Q1 | AO7: 2020-Q2 | AP7: 2020-Q3 | AQ7: 2020-Q4 | AR7: 2021-Q1 | AS7: 2021-Q2 | AT7: 2021-Q3 | AU7: 2021-Q4 | AV7: 2022-Q1 | AW7: 2022-Q2 | AX7: 2022-Q3 | AY7: 2022-Q4 | AZ7: 2023-Q1 | BA7: 2023-Q2 | BB7: 2023-Q3 | BC7: 2023-Q4 | BD7: 2024-Q1 | BE7: 2024-Q2 | BF7: 2024-Q3 | BG7: 2024-Q4 | BH7: 2025-Q1 | BI7: 2025-Q2 | BJ7: 2025-Q3
B8: Reference area
B9: Lesser Poland | D9: 4.2 | E9: -1.3 | F9: 0.3 | G9: -0.3 | H9: -1.7 | I9: 0.3 | J9: -5.6 | K9: -6 | L9: -8.1 | M9: -7.7 | N9: -3.5 | O9: -1.3 | P9: 4.3 | Q9: 6.8 | R9: 1.9 | S9: 2.7 | T9: 1.5 | U9: -1.4 | V9: 3.7 | W9: 0.9 | X9: 2.7 | Y9: -2.9 | Z9: -0.6 | AA9: 6.5 | AB9: 1.6 | AC9: 8.8 | AD9: 4.5 | AE9: 1.9 | AF9: 5.7 | AG9: 4.7 | AH9: 1.3 | AI9: 5.8 | AJ9: 8.1 | AK9: 10.3 | AL9: 9.5 | AM9: 6.6 | AN9: 7.6 | AO9: 7.6 | AP9: 13.5 | AQ9: 7.5 | AR9: 5.9 | AS9: 6.6 | AT9: 9.2 | AU9: 13.9 | AV9: 14.5 | AW9: 12.3 | AX9: 11.5 | AY9: 11.5 | AZ9: 10.7 | BA9: 9.4 | BB9: 14.2 | BC9: 18.6 | BD9: 24.5 | BE9: 24.6 | BF9: 18.6 | BG9: 10.2 | BH9: 2.9 | BI9: 3.5 | BJ9: 2.4
B10: Silesia | D10: 4.5 | E10: 3.4 | F10: 1.8 | G10: 3.4 | H10: -1.5 | I10: -1.8 | J10: -5.7 | K10: -4.9 | L10: -6.1 | M10: -4 | N10: -2.9 | O10: -3 | P10: 0.4 | Q10: 1.1 | R10: 1.6 | S10: 1 | T10: 0.6 | U10: -1 | V10: -1.4 | W10: 0.8 | X10: 1.5 | Y10: 1.8 | Z10: 4.8 | AA10: 1.5 | AB10: 2.2 | AC10: 4.5 | AD10: 1.1 | AE10: 6.7 | AF10: 7.3 | AG10: 7.3 | AH10: 12.5 | AI10: 10.1 | AJ10: 11 | AK10: 10.4 | AL10: 10.5 | AM10: 11.5 | AN10: 15.9 | AO10: 16.2 | AP10: 14.5 | AQ10: 13.8 | AR10: 9.4 | AS10: 10.2 | AT10: 13 | AU10: 14 | AV10: 14.6 | AW10: 13 | AX10: 9 | AY10: 7.7 | AZ10: 3.2 | BA10: 3.8 | BB10: 8.5 | BC10: 12.7 | BD10: 19.1 | BE10: 20.3 | BF10: 17.6 | BG10: 13.5 | BH10: 9 | BI10: 5.4 | BJ10: 2.9
B11: Greater Poland | D11: -0.3 | E11: 0.7 | F11: -4.2 | G11: 1 | H11: 0.1 | I11: -2.8 | J11: -2.9 | K11: -5.8 | L11: -6.5 | M11: -3.4 | N11: -1.4 | O11: 1.2 | P11: -0.6 | Q11: 1.9 | R11: 3.6 | S11: 0.7 | T11: 3.1 | U11: 1.6 | V11: 0.8 | W11: 3.4 | X11: 1.1 | Y11: 0.7 | Z11: 2.4 | AA11: 0.9 | AB11: 3.3 | AC11: 2.6 | AD11: 0.8 | AE11: 1.4 | AF11: 4.1 | AG11: 7.3 | AH11: 7.6 | AI11: 9 | AJ11: 8.6 | AK11: 9.6 | AL11: 8.7 | AM11: 8.3 | AN11: 7.6 | AO11: 8 | AP11: 9.5 | AQ11: 10.9 | AR11: 10.4 | AS11: 7.6 | AT11: 8.3 | AU11: 10.5 | AV11: 11.9 | AW11: 13.7 | AX11: 19.4 | AY11: 12.5 | AZ11: 8.7 | BA11: 6.6 | BB11: 5.1 | BC11: 12.1 | BD11: 16.5 | BE11: 20.5 | BF11: 14.1 | BG11: 11 | BH11: 7.9 | BI11: 4.4 | BJ11: 5.9
B12: West Pomerania | D12: -0.9 | E12: -8.2 | F12: -3.7 | G12: -7.6 | H12: -5 | I12: -0.5 | J12: -5.7 | K12: -3.1 | L12: -2.7 | M12: -0.2 | N12: 1.3 | O12: -1.9 | P12: -0.9 | Q12: -0.1 | R12: 1 | S12: 2.3 | T12: 0.6 | U12: 1.2 | V12: -3.9 | W12: -2.7 | X12: -0.2 | Y12: -0.9 | Z12: 2.9 | AA12: 2.5 | AB12: 2.5 | AC12: 2.3 | AD12: 5.5 | AE12: 8.3 | AF12: 9.6 | AG12: 11.1 | AH12: 11.3 | AI12: 8.5 | AJ12: 7.5 | AK12: 10.2 | AL12: 6.7 | AM12: 12.8 | AN12: 16.8 | AO12: 10 | AP12: 11.2 | AQ12: 8.2 | AR12: 4.5 | AS12: 8.3 | AT12: 10.2 | AU12: 13.1 | AV12: 17.8 | AW12: 20 | AX12: 14.8 | AY12: 11.7 | AZ12: 6.2 | BA12: 0.4 | BB12: 3.6 | BC12: 1.2 | BD12: 7.1 | BE12: 10.5 | BF12: 6.2 | BG12: 7.6 | BH12: 2.1 | BI12: 0.8 | BJ12: 3.7
B13: Lubusz | D13: 1.5 | E13: 2.3 | F13: 0.8 | G13: 3.1 | H13: -2 | I13: -1.5 | J13: -3.1 | K13: -3.4 | L13: -0.2 | M13: -2.6 | N13: -2.8 | O13: 1.9 | P13: 1 | Q13: 2.8 | R13: 3.2 | S13: 0.9 | T13: 0.7 | U13: 2.8 | V13: 2.1 | W13: 1.6 | X13: 2.1 | Y13: 2 | Z13: 5.3 | AA13: 2.2 | AB13: 2.2 | AC13: 3.5 | AD13: 5.3 | AE13: 4.1 | AF13: 5 | AG13: 8.2 | AH13: 5.3 | AI13: 9.2 | AJ13: 9.3 | AK13: 6.3 | AL13: 9.4 | AM13: 9.5 | AN13: 16.9 | AO13: 12.7 | AP13: 8.5 | AQ13: 13 | AR13: 3.8 | AS13: 7.5 | AT13: 8.4 | AU13: 7.6 | AV13: 9.7 | AW13: 10 | AX13: 14 | AY13: 8.7 | AZ13: 8.7 | BA13: 5.1 | BB13: 8.2 | BC13: 15 | BD13: 20.6 | BE13: 22.5 | BF13: 16.4 | BG13: 11.1 | BH13: 4.8 | BI13: 4.4 | BJ13: 3.9
B14: Lower Silesia | D14: 6 | E14: 2.3 | F14: 0.9 | G14: -1.6 | H14: -4.4 | I14: -5.2 | J14: -5.4 | K14: -5.8 | L14: -5.5 | M14: -4.3 | N14: -4.2 | O14: -1.9 | P14: -2.1 | Q14: 2.8 | R14: 1.9 | S14: 0.1 | T14: 3.4 | U14: -4.2 | V14: -0.4 | W14: 0.9 | X14: -0.1 | Y14: 1.7 | Z14: 2.7 | AA14: 4.9 | AB14: 3.5 | AC14: 5.9 | AD14: 4.1 | AE14: 1.4 | AF14: 0 | AG14: -0.8 | AH14: 3.4 | AI14: 9.1 | AJ14: 12.1 | AK14: 12 | AL14: 10.1 | AM14: 6.7 | AN14: 10.9 | AO14: 12.6 | AP14: 10.5 | AQ14: 12.3 | AR14: 9.8 | AS14: 9.5 | AT14: 10.6 | AU14: 11.9 | AV14: 15.6 | AW14: 12.5 | AX14: 11.5 | AY14: 10 | AZ14: 4.9 | BA14: 12.1 | BB14: 15 | BC14: 18.3 | BD14: 21.5 | BE14: 17.4 | BF14: 15.1 | BG14: 11.7 | BH14: 8.2 | BI14: 6.7 | BJ14: 4.8
